Workbook
Name ER: '4.관항목정리목록 (2)'!#REF!
Name ER: #REF!
Name 관: '4.관항목정리목록 (2)'!$B$5:$B$8
Name 관: #REF!
Name 관리운영비: '4.관항목정리목록 (2)'!#REF!
Name 관리운영비: #REF!
Name 교육자료제작: '4.관항목정리목록 (2)'!#REF!
Name 교육자료제작: #REF!
Name 근거자료: #REF!
Name 목: '4.관항목정리목록 (2)'!$D$4:$D$8
Name 사업비: 결과정산보고서!$C$9:$C$18
Name 사업외비용: '4.관항목정리목록 (2)'!#REF!
Name 사업외비용: #REF!
Name 사업외수입: '4.관항목정리목록 (2)'!#REF!
Name 사업외수입: #REF!
Name 세목: '4.관항목정리목록 (2)'!#REF!
Name 세목: #REF!
Name 수입: '4.관항목정리목록 (2)'!$E$7:$G$7
Name 수입: 결과정산보고서!$D$44:$D$46
Name 우산수리교육워크숍: '4.관항목정리목록 (2)'!#REF!
Name 우산수리교육워크숍: 결과정산보고서!$C$9:$C$10
Name 운영비: '4.관항목정리목록 (2)'!#REF!
Name 운영비: 결과정산보고서!$C$20
Name 유형: '4.관항목정리목록 (2)'!#REF!
Name 유형: #REF!
Name 인건비: '4.관항목정리목록 (2)'!#REF!
Name 인건비: #REF!
Name 전담인력: '4.관항목정리목록 (2)'!#REF!
Name 전담인력: #REF!
Name 증빙종류: '4.관항목정리목록 (2)'!#REF!
Name 증빙종류: #REF!
Name 학교참여수거모델개발: '4.관항목정리목록 (2)'!#REF!
Name 학교참여수거모델개발: #REF!
Name 홍보비: '4.관항목정리목록 (2)'!#REF!
Name 홍보비: #REF!
Name 후원금수입: '4.관항목정리목록 (2)'!#REF!
Name 후원금수입: #REF!

Sheet 결과정산보고서
A1: 시민아이디어지원사업 풀씨 12기 활동 정산보고서
A4: 팀명 | E4: 대표자 | G4: 활동기간 | H4: 2025.04.01 - 09.30
A5: 활동명
A6: 예산계획서 ※ 지원 당시 또는 승인된 예산변경계획서 | F6: 정산보고서 ※실제 집행된 내용
A7: 구분 | D7: 내용 | E7: 금 액(원) | F7: 내용(산출근거) | L7: 사용액(원) | M7: 잔액(원)
A8: 항 | B8: 세목 | C8: 세세목
A9: 사업비 | B9: 세목1 | C9: 세세목1 | E9: 50000 | F9: {=_xlfn.TEXTJOIN(CHAR(10),TRUE,IF(활동비지출일별내역!C$7:C$168=결과정산보고서!C9,활동비지출일별내역!K$7:K$168,""))} -> 04월12일/ 팀 활동 홍보물 제작(포스터 1종)/풀씨디자인/50000 | L9: =SUMIF(활동비지출일별내역!C$7:C$168,결과정산보고서!C9,활동비지출일별내역!G$7:G$168) -> 50000 | M9: =E9-L9 -> 0
B10: 세목2 | C10: 세세목2 | E10: 200000 | F10: {=_xlfn.TEXTJOIN(CHAR(10),TRUE,IF(활동비지출일별내역!C$7:C$168=결과정산보고서!C10,활동비지출일별내역!K$7:K$168,""))} -> 04월13일/ 4/19 행사 다과비(과자 100인분, 음료 100인분)/쿠팡과자점/200000 04월17일/ 4/19 행사 홍보물 제작비/풀씨인쇄소/20000 | L10: =SUMIF(활동비지출일별내역!C$7:C$168,결과정산보고서!C10,활동비지출일별내역!G$7:G$168) -> 220000 | M10: =E10-L10 -> -20000
B11: 세목3 | C11: 세세목3 | E11: 100000 | F11: {=_xlfn.TEXTJOIN(CHAR(10),TRUE,IF(활동비지출일별내역!C$7:C$168=결과정산보고서!C11,활동비지출일별내역!K$7:K$168,""))} -> 05월04일/ 5/8일 행사 다과비(과자 50인분, 음료 50인분)/쿠팡과자점/100000 | L11: =SUMIF(활동비지출일별내역!C$7:C$168,결과정산보고서!C11,활동비지출일별내역!G$7:G$168) -> 100000 | M11: =E11-L11 -> 0
C12: 세세목4 | E12: 150000 | F12: {=_xlfn.TEXTJOIN(CHAR(10),TRUE,IF(활동비지출일별내역!C$7:C$168=결과정산보고서!C12,활동비지출일별내역!K$7:K$168,""))} -> 05월04일/ 5/15 교육프로그램 위한 가위, 풀 10인용 문구 구입 /풀씨문방구/160000 | L12: =SUMIF(활동비지출일별내역!C$7:C$168,결과정산보고서!C12,활동비지출일별내역!G$7:G$168) -> 160000 | M12: =E12-L12 -> -10000
B13: 세목4 | C13: 세세목5 | E13: 350000 | F13: {=_xlfn.TEXTJOIN(CHAR(10),TRUE,IF(활동비지출일별내역!C$7:C$168=결과정산보고서!C13,활동비지출일별내역!K$7:K$168,""))} -> 05월12일/ 5/15 워크숍 숙박비 (8명*3방*1박)/풀씨호텔/400000 | L13: =SUMIF(활동비지출일별내역!C$7:C$168,결과정산보고서!C13,활동비지출일별내역!G$7:G$168) -> 400000 | M13: =E13-L13 -> -50000
C14: 세세목6 | E14: 200000 | F14: {=_xlfn.TEXTJOIN(CHAR(10),TRUE,IF(활동비지출일별내역!C$7:C$168=결과정산보고서!C14,활동비지출일별내역!K$7:K$168,""))} -> 05월15일/ 5/15 워크숍 아침 (8명)/풀씨식당/80000 05월15일/ 5/15 워크숍 점심 (8명)/풀꽃식당/80000 05월15일/ 5/16 워크숍 아침 (8명 *4,000원)/풀씨김밥/50000 | L14: =SUMIF(활동비지출일별내역!C$7:C$168,결과정산보고서!C14,활동비지출일별내역!G$7:G$168) -> 210000 | M14: =E14-L14 -> -10000
C15: 세세목7 | E15: 450000 | F15: {=_xlfn.TEXTJOIN(CHAR(10),TRUE,IF(활동비지출일별내역!C$7:C$168=결과정산보고서!C15,활동비지출일별내역!K$7:K$168,""))} -> 05월15일/ 5/15 워크숍 시외버스 (대구<->서울) 왕복 8명/KOBUS/450000 | L15: =SUMIF(활동비지출일별내역!C$7:C$168,결과정산보고서!C15,활동비지출일별내역!G$7:G$168) -> 450000 | M15: =E15-L15 -> 0
B16: 세목5 | C16: 세세목8 | E16: 1150000 | F16: {=_xlfn.TEXTJOIN(CHAR(10),TRUE,IF(활동비지출일별내역!C$7:C$168=결과정산보고서!C16,활동비지출일별내역!K$7:K$168,""))} -> 08월20일/ 9/30 행사 홍보물 제작 (포스터 및 쇼츠 영상 1종)/풀씨홍보/900000 08월25일/ 9/30 행사 인스타 홍보 (7일 * 30달러)/Instagram/210000 | L16: =SUMIF(활동비지출일별내역!C$7:C$168,결과정산보고서!C16,활동비지출일별내역!G$7:G$168) -> 1110000 | M16: =E16-L16 -> 40000
C17: 세세목9 | E17: 250000 | F17: {=_xlfn.TEXTJOIN(CHAR(10),TRUE,IF(활동비지출일별내역!C$7:C$168=결과정산보고서!C17,활동비지출일별내역!K$7:K$168,""))} -> 09월27일/ 9/30 행사 강사비(1명)/김풀꽃/228000 09월27일/ 9/30 행사 강사비 세금 신고건/재단법인 숲과나눔/22000 | L17: =SUMIF(활동비지출일별내역!C$7:C$168,결과정산보고서!C17,활동비지출일별내역!G$7:G$168) -> 250000 | M17: =E17-L17 -> 0
B18: 세목6 | C18: 세세목10 | E18: 50000 | F18: {=_xlfn.TEXTJOIN(CHAR(10),TRUE,IF(활동비지출일별내역!C$7:C$168=결과정산보고서!C18,활동비지출일별내역!K$7:K$168,""))} -> 05월10일/ 5/10인터뷰 면담 진행비 20,000*1인/김풀씨/20000 | L18: =SUMIF(활동비지출일별내역!C$7:C$168,결과정산보고서!C18,활동비지출일별내역!G$7:G$168) -> 20000 | M18: =E18-L18 -> 30000
C19: 수입 | D19: 소 계 | E19: =SUM(E7:E18) -> 2950000 | F19: 소 계 | L19: =SUM(L9:L18) -> 2970000 | M19: =E19-L19 -> -20000
A20: 운영비 | C20: 운영비 | E20: 50000 | F20: {=_xlfn.TEXTJOIN(CHAR(10),TRUE,IF(활동비지출일별내역!C$7:C$168=결과정산보고서!C20,활동비지출일별내역!K$7:K$168,""))} -> 05월12일/ 워크숍 전 회의 식비 15,000*2인/풀씨인쇄소/30000 09월27일/ 이체수수료/풀씨은행/500 | L20: =SUMIF(활동비지출일별내역!C$7:C$168,결과정산보고서!C20,활동비지출일별내역!G$7:G$168) -> 30500 | M20: =E20-L20 -> 19500
B21: 수입 | C21: 합 계 | E21: =SUM(E9:E20)-E19 -> 3000000 | F21: 잔액환급여부 | L21: =SUM(L20,L19) -> 3000500 | M21: =E21-L21 -> -500
B22: 이자, 캐시백 | E22: =SUMIF(활동비지출일별내역!C6:C168,"이자",활동비지출일별내역!G6:G168)+SUMIF(활동비지출일별내역!C6:C168,"캐시백",활동비지출일별내역!G6:G168) -> 1340 | F22: 환급액 | G22: =IF(M22<=10000,0,M22) -> 0 | H22: =IF(G22>0,"환급요망","환급불필요") -> 환급불필요 | I22: 환급날짜 | L22: 최종잔액 (통장잔액, 환급전) | M22: =M21+E22 -> 840
A23: * 첨부서류 : 활동비 통장거래내역 1부, 90만원 이상 항목의 견적서 활동비 사용기준표에 의하여 위와 같이 활동비 사용내역을 보고합니다. 2025 년 월 일 팀명 또는 개인 : (인) (재)숲과나눔 이사장 귀하
D44: 이자
D45: 캐시백
D46: 활동비

Sheet 활동비지출일별내역
A1: 시민아이디어지원사업 풀씨 11기 활동비지출일별내역 <2025.04.01 ∼ 2025.09.30> ※ 아래 내용은 예시로 작성했습니다. 참고하시고 삭제하고 작성해주세요. (온라인 통장거래내역을 엑셀로 다운받으시면 좀 더 편하게 수정하실 수 있습니다.)
A4: 팀명 | C4: 거래은행 | E4: ↓지출한 사유를 자세히 적어주세요 | G4: 총 지출액 | H4: 최종 잔액 | I4: * 90만원 이상시 견적서 제출 *인건비 12만5천 이상시 세금 신고
A5: 계좌번호 | F5: 0 | G5: =SUMIF(B7:B169,"<>"&"수입",G7:G222) -> 3000500 | H5: =H169 -> 840
A6: 순서 | B6: 항 | C6: 세세목 | D6: 거래일자 | E6: 내용 | F6: 거래처명 | G6: 수입/지출금액 | H6: 잔액 | I6: 구분 | J6: 비고 | K6: 열1
A7: 1 | B7: 수입 | C7: 활동비 | D7: 45381 | E7: 활동비입금 | F7: 재단법인 숲과나눔 | G7: 3000000 | H7: =F5+IF(표1[[#This Row],[항]]="수입",표1[[#This Row],[수입/지출금액]],(-1*표1[[#This Row],[수입/지출금액]])) -> 3000000 | K7: =TEXT(표1[[#This Row],[거래일자]],"mm월dd일/")&" "&표1[[#This Row],[내용]]&"/"&표1[[#This Row],[거래처명]]&"/"&표1[[#This Row],[수입/지출금액]] -> 03월30일/ 활동비입금/재단법인 숲과나눔/3000000
A8: 2 | B8: 사업비 | C8: 세세목1 | D8: 45394 | E8: 팀 활동 홍보물 제작(포스터 1종) | F8: 풀씨디자인 | G8: 50000 | H8: =H7+IF(표1[[#This Row],[항]]="수입",표1[[#This Row],[수입/지출금액]],(-1*표1[[#This Row],[수입/지출금액]])) -> 2950000 | I8: 카드 | K8: =TEXT(표1[[#This Row],[거래일자]],"mm월dd일/")&" "&표1[[#This Row],[내용]]&"/"&표1[[#This Row],[거래처명]]&"/"&표1[[#This Row],[수입/지출금액]] -> 04월12일/ 팀 활동 홍보물 제작(포스터 1종)/풀씨디자인/50000
A9: 3 | B9: 사업비 | C9: 세세목2 | D9: 45395 | E9: 4/19 행사 다과비(과자 100인분, 음료 100인분) | F9: 쿠팡과자점 | G9: 200000 | H9: =H8+IF(표1[[#This Row],[항]]="수입",표1[[#This Row],[수입/지출금액]],(-1*표1[[#This Row],[수입/지출금액]])) -> 2750000 | I9: 카드 | J9: 네이버페이 | K9: =TEXT(표1[[#This Row],[거래일자]],"mm월dd일/")&" "&표1[[#This Row],[내용]]&"/"&표1[[#This Row],[거래처명]]&"/"&표1[[#This Row],[수입/지출금액]] -> 04월13일/ 4/19 행사 다과비(과자 100인분, 음료 100인분)/쿠팡과자점/200000
A10: 4 | B10: 사업비 | C10: 세세목2 | D10: 45399 | E10: 4/19 행사 홍보물 제작비 | F10: 풀씨인쇄소 | G10: 20000 | H10: =H9+IF(표1[[#This Row],[항]]="수입",표1[[#This Row],[수입/지출금액]],(-1*표1[[#This Row],[수입/지출금액]])) -> 2730000 | I10: 카드 | K10: =TEXT(표1[[#This Row],[거래일자]],"mm월dd일/")&" "&표1[[#This Row],[내용]]&"/"&표1[[#This Row],[거래처명]]&"/"&표1[[#This Row],[수입/지출금액]] -> 04월17일/ 4/19 행사 홍보물 제작비/풀씨인쇄소/20000
A11: 5 | B11: 사업비 | C11: 세세목3 | D11: 45416 | E11: 5/8일 행사 다과비(과자 50인분, 음료 50인분) | F11: 쿠팡과자점 | G11: 100000 | H11: =H10+IF(표1[[#This Row],[항]]="수입",표1[[#This Row],[수입/지출금액]],(-1*표1[[#This Row],[수입/지출금액]])) -> 2630000 | I11: 카드 | K11: =TEXT(표1[[#This Row],[거래일자]],"mm월dd일/")&" "&표1[[#This Row],[내용]]&"/"&표1[[#This Row],[거래처명]]&"/"&표1[[#This Row],[수입/지출금액]] -> 05월04일/ 5/8일 행사 다과비(과자 50인분, 음료 50인분)/쿠팡과자점/100000
A12: 6 | B12: 사업비 | C12: 세세목4 | D12: 45416 | E12: 5/15 교육프로그램 위한 가위, 풀 10인용 문구 구입 | F12: 풀씨문방구 | G12: 160000 | H12: =H11+IF(표1[[#This Row],[항]]="수입",표1[[#This Row],[수입/지출금액]],(-1*표1[[#This Row],[수입/지출금액]])) -> 2470000 | I12: 카드 | J12: 쿠팡 | K12: =TEXT(표1[[#This Row],[거래일자]],"mm월dd일/")&" "&표1[[#This Row],[내용]]&"/"&표1[[#This Row],[거래처명]]&"/"&표1[[#This Row],[수입/지출금액]] -> 05월04일/ 5/15 교육프로그램 위한 가위, 풀 10인용 문구 구입 /풀씨문방구/160000
A13: 7 | B13: 수입 | C13: 이자 | D13: 45422 | E13: 이자 | F13: 풀씨은행 | G13: 670 | H13: =H12+IF(표1[[#This Row],[항]]="수입",표1[[#This Row],[수입/지출금액]],(-1*표1[[#This Row],[수입/지출금액]])) -> 2470670 | K13: =TEXT(표1[[#This Row],[거래일자]],"mm월dd일/")&" "&표1[[#This Row],[내용]]&"/"&표1[[#This Row],[거래처명]]&"/"&표1[[#This Row],[수입/지출금액]] -> 05월10일/ 이자/풀씨은행/670
A14: 8 | B14: 사업비 | C14: 세세목10 | D14: 45422 | E14: 5/10인터뷰 면담 진행비 20,000*1인 | F14: 김풀씨 | G14: 20000 | H14: =H13+IF(표1[[#This Row],[항]]="수입",표1[[#This Row],[수입/지출금액]],(-1*표1[[#This Row],[수입/지출금액]])) -> 2450670 | I14: 이체 | K14: =TEXT(표1[[#This Row],[거래일자]],"mm월dd일/")&" "&표1[[#This Row],[내용]]&"/"&표1[[#This Row],[거래처명]]&"/"&표1[[#This Row],[수입/지출금액]] -> 05월10일/ 5/10인터뷰 면담 진행비 20,000*1인/김풀씨/20000
A15: 9 | B15: 운영비 | C15: 운영비 | D15: 45424 | E15: 워크숍 전 회의 식비 15,000*2인 | F15: 풀씨인쇄소 | G15: 30000 | H15: =H14+IF(표1[[#This Row],[항]]="수입",표1[[#This Row],[수입/지출금액]],(-1*표1[[#This Row],[수입/지출금액]])) -> 2420670 | I15: 카드 | K15: =TEXT(표1[[#This Row],[거래일자]],"mm월dd일/")&" "&표1[[#This Row],[내용]]&"/"&표1[[#This Row],[거래처명]]&"/"&표1[[#This Row],[수입/지출금액]] -> 05월12일/ 워크숍 전 회의 식비 15,000*2인/풀씨인쇄소/30000
A16: 10 | B16: 사업비 | C16: 세세목5 | D16: 45424 | E16: 5/15 워크숍 숙박비 (8명*3방*1박) | F16: 풀씨호텔 | G16: 400000 | H16: =H15+IF(표1[[#This Row],[항]]="수입",표1[[#This Row],[수입/지출금액]],(-1*표1[[#This Row],[수입/지출금액]])) -> 2020670 | I16: 카드 | K16: =TEXT(표1[[#This Row],[거래일자]],"mm월dd일/")&" "&표1[[#This Row],[내용]]&"/"&표1[[#This Row],[거래처명]]&"/"&표1[[#This Row],[수입/지출금액]] -> 05월12일/ 5/15 워크숍 숙박비 (8명*3방*1박)/풀씨호텔/400000
A17: 11 | B17: 사업비 | C17: 세세목6 | D17: 45427 | E17: 5/15 워크숍 아침 (8명) | F17: 풀씨식당 | G17: 80000 | H17: =H16+IF(표1[[#This Row],[항]]="수입",표1[[#This Row],[수입/지출금액]],(-1*표1[[#This Row],[수입/지출금액]])) -> 1940670 | I17: 카드 | K17: =TEXT(표1[[#This Row],[거래일자]],"mm월dd일/")&" "&표1[[#This Row],[내용]]&"/"&표1[[#This Row],[거래처명]]&"/"&표1[[#This Row],[수입/지출금액]] -> 05월15일/ 5/15 워크숍 아침 (8명)/풀씨식당/80000
A18: 12 | B18: 사업비 | C18: 세세목7 | D18: 45427 | E18: 5/15 워크숍 시외버스 (대구<->서울) 왕복 8명 | F18: KOBUS | G18: 450000 | H18: =H17+IF(표1[[#This Row],[항]]="수입",표1[[#This Row],[수입/지출금액]],(-1*표1[[#This Row],[수입/지출금액]])) -> 1490670 | I18: 카드 | K18: =TEXT(표1[[#This Row],[거래일자]],"mm월dd일/")&" "&표1[[#This Row],[내용]]&"/"&표1[[#This Row],[거래처명]]&"/"&표1[[#This Row],[수입/지출금액]] -> 05월15일/ 5/15 워크숍 시외버스 (대구<->서울) 왕복 8명/KOBUS/450000
A19: 13 | B19: 사업비 | C19: 세세목6 | D19: 45427 | E19: 5/15 워크숍 점심 (8명) | F19: 풀꽃식당 | G19: 80000 | H19: =H18+IF(표1[[#This Row],[항]]="수입",표1[[#This Row],[수입/지출금액]],(-1*표1[[#This Row],[수입/지출금액]])) -> 1410670 | I19: 카드 | K19: =TEXT(표1[[#This Row],[거래일자]],"mm월dd일/")&" "&표1[[#This Row],[내용]]&"/"&표1[[#This Row],[거래처명]]&"/"&표1[[#This Row],[수입/지출금액]] -> 05월15일/ 5/15 워크숍 점심 (8명)/풀꽃식당/80000
A20: 14 | B20: 사업비 | C20: 세세목6 | D20: 45427 | E20: 5/16 워크숍 아침 (8명 *4,000원) | F20: 풀씨김밥 | G20: 50000 | H20: =H19+IF(표1[[#This Row],[항]]="수입",표1[[#This Row],[수입/지출금액]],(-1*표1[[#This Row],[수입/지출금액]])) -> 1360670 | I20: 카드 | K20: =TEXT(표1[[#This Row],[거래일자]],"mm월dd일/")&" "&표1[[#This Row],[내용]]&"/"&표1[[#This Row],[거래처명]]&"/"&표1[[#This Row],[수입/지출금액]] -> 05월15일/ 5/16 워크숍 아침 (8명 *4,000원)/풀씨김밥/50000
A21: 15 | B21: 사업비 | C21: 세세목8 | D21: 45524 | E21: 9/30 행사 홍보물 제작 (포스터 및 쇼츠 영상 1종) | F21: 풀씨홍보 | G21: 900000 | H21: =H20+IF(표1[[#This Row],[항]]="수입",표1[[#This Row],[수입/지출금액]],(-1*표1[[#This Row],[수입/지출금액]])) -> 460670 | I21: 카드 | J21: 견적서 제출 | K21: =TEXT(표1[[#This Row],[거래일자]],"mm월dd일/")&" "&표1[[#This Row],[내용]]&"/"&표1[[#This Row],[거래처명]]&"/"&표1[[#This Row],[수입/지출금액]] -> 08월20일/ 9/30 행사 홍보물 제작 (포스터 및 쇼츠 영상 1종)/풀씨홍보/900000
A22: 16 | B22: 사업비 | C22: 세세목8 | D22: 45529 | E22: 9/30 행사 인스타 홍보 (7일 * 30달러) | F22: Instagram | G22: 210000 | H22: =H21+IF(표1[[#This Row],[항]]="수입",표1[[#This Row],[수입/지출금액]],(-1*표1[[#This Row],[수입/지출금액]])) -> 250670 | I22: 카드 | K22: =TEXT(표1[[#This Row],[거래일자]],"mm월dd일/")&" "&표1[[#This Row],[내용]]&"/"&표1[[#This Row],[거래처명]]&"/"&표1[[#This Row],[수입/지출금액]] -> 08월25일/ 9/30 행사 인스타 홍보 (7일 * 30달러)/Instagram/210000
A23: 17 | B23: 사업비 | C23: 세세목9 | D23: 45562 | E23: 9/30 행사 강사비(1명) | F23: 김풀꽃 | G23: =250000-22000 -> 228000 | H23: =H22+IF(표1[[#This Row],[항]]="수입",표1[[#This Row],[수입/지출금액]],(-1*표1[[#This Row],[수입/지출금액]])) -> 22670 | I23: 이체 | J23: 인건비 | K23: =TEXT(표1[[#This Row],[거래일자]],"mm월dd일/")&" "&표1[[#This Row],[내용]]&"/"&표1[[#This Row],[거래처명]]&"/"&표1[[#This Row],[수입/지출금액]] -> 09월27일/ 9/30 행사 강사비(1명)/김풀꽃/228000
A24: 18 | B24: 사업비 | C24: 세세목9 | D24: 45562 | E24: 9/30 행사 강사비 세금 신고건 | F24: 재단법인 숲과나눔 | G24: 22000 | H24: =H23+IF(표1[[#This Row],[항]]="수입",표1[[#This Row],[수입/지출금액]],(-1*표1[[#This Row],[수입/지출금액]])) -> 670 | I24: 이체 | J24: 세금신고 | K24: =TEXT(표1[[#This Row],[거래일자]],"mm월dd일/")&" "&표1[[#This Row],[내용]]&"/"&표1[[#This Row],[거래처명]]&"/"&표1[[#This Row],[수입/지출금액]] -> 09월27일/ 9/30 행사 강사비 세금 신고건/재단법인 숲과나눔/22000
A25: 19 | B25: 운영비 | C25: 운영비 | D25: 45562 | E25: 이체수수료 | F25: 풀씨은행 | G25: 500 | H25: =H24+IF(표1[[#This Row],[항]]="수입",표1[[#This Row],[수입/지출금액]],(-1*표1[[#This Row],[수입/지출금액]])) -> 170 | K25: =TEXT(표1[[#This Row],[거래일자]],"mm월dd일/")&" "&표1[[#This Row],[내용]]&"/"&표1[[#This Row],[거래처명]]&"/"&표1[[#This Row],[수입/지출금액]] -> 09월27일/ 이체수수료/풀씨은행/500
A26: 20 | B26: 수입 | C26: 캐시백 | D26: 45564 | E26: 카드 캐시백 | F26: 풀씨은행 | G26: 670 | H26: =H25+IF(표1[[#This Row],[항]]="수입",표1[[#This Row],[수입/지출금액]],(-1*표1[[#This Row],[수입/지출금액]])) -> 840 | K26: =TEXT(표1[[#This Row],[거래일자]],"mm월dd일/")&" "&표1[[#This Row],[내용]]&"/"&표1[[#This Row],[거래처명]]&"/"&표1[[#This Row],[수입/지출금액]] -> 09월29일/ 카드 캐시백/풀씨은행/670
A27: 21 | H27: =H26+IF(표1[[#This Row],[항]]="수입",표1[[#This Row],[수입/지출금액]],(-1*표1[[#This Row],[수입/지출금액]])) -> 840 | K27: =TEXT(표1[[#This Row],[거래일자]],"mm월dd일/")&" "&표1[[#This Row],[내용]]&"/"&표1[[#This Row],[거래처명]]&"/"&표1[[#This Row],[수입/지출금액]] -> 01월00일/ //
A28: 22 | H28: =H27+IF(표1[[#This Row],[항]]="수입",표1[[#This Row],[수입/지출금액]],(-1*표1[[#This Row],[수입/지출금액]])) -> 840 | K28: =TEXT(표1[[#This Row],[거래일자]],"mm월dd일/")&" "&표1[[#This Row],[내용]]&"/"&표1[[#This Row],[거래처명]]&"/"&표1[[#This Row],[수입/지출금액]] -> 01월00일/ //
A29: 23 | H29: =H28+IF(표1[[#This Row],[항]]="수입",표1[[#This Row],[수입/지출금액]],(-1*표1[[#This Row],[수입/지출금액]])) -> 840 | K29: =TEXT(표1[[#This Row],[거래일자]],"mm월dd일/")&" "&표1[[#This Row],[내용]]&"/"&표1[[#This Row],[거래처명]]&"/"&표1[[#This Row],[수입/지출금액]] -> 01월00일/ //
A30: 24 | H30: =H29+IF(표1[[#This Row],[항]]="수입",표1[[#This Row],[수입/지출금액]],(-1*표1[[#This Row],[수입/지출금액]])) -> 840 | K30: =TEXT(표1[[#This Row],[거래일자]],"mm월dd일/")&" "&표1[[#This Row],[내용]]&"/"&표1[[#This Row],[거래처명]]&"/"&표1[[#This Row],[수입/지출금액]] -> 01월00일/ //
A31: 25 | H31: =H30+IF(표1[[#This Row],[항]]="수입",표1[[#This Row],[수입/지출금액]],(-1*표1[[#This Row],[수입/지출금액]])) -> 840 | K31: =TEXT(표1[[#This Row],[거래일자]],"mm월dd일/")&" "&표1[[#This Row],[내용]]&"/"&표1[[#This Row],[거래처명]]&"/"&표1[[#This Row],[수입/지출금액]] -> 01월00일/ //
A32: 26 | H32: =H31+IF(표1[[#This Row],[항]]="수입",표1[[#This Row],[수입/지출금액]],(-1*표1[[#This Row],[수입/지출금액]])) -> 840 | K32: =TEXT(표1[[#This Row],[거래일자]],"mm월dd일/")&" "&표1[[#This Row],[내용]]&"/"&표1[[#This Row],[거래처명]]&"/"&표1[[#This Row],[수입/지출금액]] -> 01월00일/ //
A33: 27 | H33: =H32+IF(표1[[#This Row],[항]]="수입",표1[[#This Row],[수입/지출금액]],(-1*표1[[#This Row],[수입/지출금액]])) -> 840 | K33: =TEXT(표1[[#This Row],[거래일자]],"mm월dd일/")&" "&표1[[#This Row],[내용]]&"/"&표1[[#This Row],[거래처명]]&"/"&표1[[#This Row],[수입/지출금액]] -> 01월00일/ //
A34: 28 | H34: =H33+IF(표1[[#This Row],[항]]="수입",표1[[#This Row],[수입/지출금액]],(-1*표1[[#This Row],[수입/지출금액]])) -> 840 | K34: =TEXT(표1[[#This Row],[거래일자]],"mm월dd일/")&" "&표1[[#This Row],[내용]]&"/"&표1[[#This Row],[거래처명]]&"/"&표1[[#This Row],[수입/지출금액]] -> 01월00일/ //
A35: 29 | H35: =H34+IF(표1[[#This Row],[항]]="수입",표1[[#This Row],[수입/지출금액]],(-1*표1[[#This Row],[수입/지출금액]])) -> 840 | K35: =TEXT(표1[[#This Row],[거래일자]],"mm월dd일/")&" "&표1[[#This Row],[내용]]&"/"&표1[[#This Row],[거래처명]]&"/"&표1[[#This Row],[수입/지출금액]] -> 01월00일/ //
A36: 30 | H36: =H35+IF(표1[[#This Row],[항]]="수입",표1[[#This Row],[수입/지출금액]],(-1*표1[[#This Row],[수입/지출금액]])) -> 840 | K36: =TEXT(표1[[#This Row],[거래일자]],"mm월dd일/")&" "&표1[[#This Row],[내용]]&"/"&표1[[#This Row],[거래처명]]&"/"&표1[[#This Row],[수입/지출금액]] -> 01월00일/ //
A37: 31 | H37: =H36+IF(표1[[#This Row],[항]]="수입",표1[[#This Row],[수입/지출금액]],(-1*표1[[#This Row],[수입/지출금액]])) -> 840 | K37: =TEXT(표1[[#This Row],[거래일자]],"mm월dd일/")&" "&표1[[#This Row],[내용]]&"/"&표1[[#This Row],[거래처명]]&"/"&표1[[#This Row],[수입/지출금액]] -> 01월00일/ //
A38: 32 | H38: =H37+IF(표1[[#This Row],[항]]="수입",표1[[#This Row],[수입/지출금액]],(-1*표1[[#This Row],[수입/지출금액]])) -> 840 | K38: =TEXT(표1[[#This Row],[거래일자]],"mm월dd일/")&" "&표1[[#This Row],[내용]]&"/"&표1[[#This Row],[거래처명]]&"/"&표1[[#This Row],[수입/지출금액]] -> 01월00일/ //
... A169: 163 | H169: =H168+IF(표1[[#This Row],[항]]="수입",표1[[#This Row],[수입/지출금액]],(-1*표1[[#This Row],[수입/지출금액]])) -> 840 | K169: =TEXT(표1[[#This Row],[거래일자]],"mm월dd일/")&" "&표1[[#This Row],[내용]]&"/"&표1[[#This Row],[거래처명]]&"/"&표1[[#This Row],[수입/지출금액]] -> 01월00일/ //
K170: =TEXT(표1[[#This Row],[거래일자]],"mm월dd일/")&" "&표1[[#This Row],[내용]]&"/"&표1[[#This Row],[거래처명]]&"/"&표1[[#This Row],[수입/지출금액]] -> 01월00일/ //
K171: =TEXT(표1[[#This Row],[거래일자]],"mm월dd일/")&" "&표1[[#This Row],[내용]]&"/"&표1[[#This Row],[거래처명]]&"/"&표1[[#This Row],[수입/지출금액]] -> 01월00일/ //
K172: =TEXT(표1[[#This Row],[거래일자]],"mm월dd일/")&" "&표1[[#This Row],[내용]]&"/"&표1[[#This Row],[거래처명]]&"/"&표1[[#This Row],[수입/지출금액]] -> 01월00일/ //
...

Sheet 4.관항목정리목록 (2)
B2: 최종 예산에 따라 관/세목/세세목을 정리해주세요. | V2: 관 | X2: 항
D3: 세세목
B4: 관 | C4: 세목 | D4: 열1 | E4: 열2 | F4: 열3 | G4: 열4 | V4: 복지부2005 | X4: 복지부2005 | Y4: 복지부2006 | Z4: 복지부2007 | AA4: 복지부2008 | AB4: 복지부2009 | AC4: 서울희망드림뱅크2009 | AD4: 국민은행2008 | AE4: 국민은행2008 | AF4: 씨티2009 | AG4: 경상회계 | AM4: 복지부2007 | AP4: 복지부2008 | AT4: 복지부2009 | AU4: 서울희망드림뱅크2009 | AV4: 국민은행2008 | AY4: 국민은행2008 | AZ4: 씨티2009 | BE4: 경상회계
B5: 사업비 | C5: 우산수리교육워크숍 | V5: 복지부2007 | Y5: 인건비 | Z5: 인건비 | AA5: 인건비 | AD5: 간접사업비 | AF5: 지역지도자양성 | AI5: 매롱 | AJ5: 얼레리 | AK5: 닐리리 | AZ5: 전문가전략회의 | BA5: 사례관리활동 | BB5: 경영컨설팅(전문가) | BC5: 운영비 | BD5: 총괄자 인건비
B6: 운영비 | C6: 홍보비 | V6: 복지부2008 | Y6: 사업경비 | Z6: 사업경비 | AA6: 사전관리 | AD6: 인건비 | AF6: 지역네트워크강화 | AI6: 매롱2 | AJ6: 얼레리2 | AK6: 닐리리2 | AZ6: 모형개발활동 | BA6: 지역지도자대표활동 | BB6: 경영컨설팅(산학협력) | BC6: 시스템분석 | BD6: 수행자인건비
B7: 수입 | C7: 수입 | E7: 이자 | F7: 캐시백 | G7: 활동비 | V7: 복지부2009 | AA7: 사후관리 | AF7: 업무시스템 | AI7: 매롱3 | AJ7: 얼레리3 | AK7: 닐리리3 | AZ7: 1차워크숍(전체) | BA7: 슈퍼비전회의 | BB7: 공동체 교육 | BC7: 시스템도입
C8: 운영비 | V8: 서울희망드림뱅크2009 | AF8: 운영비 | AI8: 매롱4 | AJ8: 얼레리4 | AK8: 닐리리4 | AZ8: 발표비 | BB8: 지회별 워크숍 | BC8: 회계감사비
V9: 국민은행2008 | AI9: 매롱5 | AJ9: 얼레리5 | AK9: 닐리리5 | AZ9: 발표자료 작성비 | BB9: 발표비

Sheet 정산보고서
C1: 통장입출금거래내역 | G1: =SUM(활동비지출일별내역!#REF!) -> #REF! | H1: =SUM(활동비지출일별내역!G7:G248) -> 6001840
C2: 통장거래내역별수지현황 | G2: =SUM(G7:G31) -> #REF! | H2: =SUM(H7:H31) -> #REF!
C3: 차액 | G3: =G1-G2 -> #REF! | H3: =H1-H2 -> #REF!
B4: 2023년 초록열매성과확산프로젝트 사업비 수지현황
B6: 계정과목 | C6: 항 | D6: 목 | E6: 산출근거 | F6: 예산액 | G6: 수입총계 | H6: 지출총계 | I6: 집행잔액 | J6: 집행비율 | K6: 비고
B7: 예금대체 | C7: 예금간거래입금 | G7: {=SUMPRODUCT((활동비지출일별내역!$B$7:$B$248=B7)*(활동비지출일별내역!#REF!=정산보고서!C7)*(활동비지출일별내역!$C$7:$C$248=정산보고서!D7)*활동비지출일별내역!#REF!)} -> #REF! | H7: {=SUMPRODUCT((활동비지출일별내역!$B$7:$B$248=B7)*(활동비지출일별내역!#REF!=정산보고서!C7)*(활동비지출일별내역!$C$7:$C$248=정산보고서!D7)*활동비지출일별내역!$G$7:$G$248)} -> #REF!
B8: 예금대체 | C8: 예금간거래출금 | G8: {=SUMPRODUCT((활동비지출일별내역!$B$7:$B$248=B8)*(활동비지출일별내역!#REF!=정산보고서!C8)*(활동비지출일별내역!$C$7:$C$248=정산보고서!D8)*활동비지출일별내역!#REF!)} -> #REF! | H8: {=SUMPRODUCT((활동비지출일별내역!$B$7:$B$248=B8)*(활동비지출일별내역!#REF!=정산보고서!C8)*(활동비지출일별내역!$C$7:$C$248=정산보고서!D8)*활동비지출일별내역!$G$7:$G$248)} -> #REF!
B9: 예금대체 | C9: 소계
B10: 수입 | C10: 후원금수입 | D10: 지정후원금수입 | G10: {=SUMPRODUCT((활동비지출일별내역!$B$7:$B$248=B10)*(활동비지출일별내역!#REF!=정산보고서!C10)*(활동비지출일별내역!$C$7:$C$248=정산보고서!D10)*활동비지출일별내역!#REF!)} -> #REF! | H10: {=SUMPRODUCT((활동비지출일별내역!$B$7:$B$248=B10)*(활동비지출일별내역!#REF!=정산보고서!C10)*(활동비지출일별내역!$C$7:$C$248=정산보고서!D10)*활동비지출일별내역!$G$7:$G$248)} -> #REF!
B11: 사업수입 | C11: 소계
B12: 사업외수익 | C12: 예금이자수입 | G12: {=SUMPRODUCT((활동비지출일별내역!$B$7:$B$248=B12)*(활동비지출일별내역!#REF!=정산보고서!C12)*(활동비지출일별내역!$C$7:$C$248=정산보고서!D12)*활동비지출일별내역!#REF!)} -> #REF! | H12: {=SUMPRODUCT((활동비지출일별내역!$B$7:$B$248=B12)*(활동비지출일별내역!#REF!=정산보고서!C12)*(활동비지출일별내역!$C$7:$C$248=정산보고서!D12)*활동비지출일별내역!$G$7:$G$248)} -> #REF!
B13: 사업외비용 | C13: 선급법인세 | G13: {=SUMPRODUCT((활동비지출일별내역!$B$7:$B$248=B13)*(활동비지출일별내역!#REF!=정산보고서!C13)*(활동비지출일별내역!$C$7:$C$248=정산보고서!D13)*활동비지출일별내역!#REF!)} -> #REF! | H13: {=SUMPRODUCT((활동비지출일별내역!$B$7:$B$248=B13)*(활동비지출일별내역!#REF!=정산보고서!C13)*(활동비지출일별내역!$C$7:$C$248=정산보고서!D13)*활동비지출일별내역!$G$7:$G$248)} -> #REF!
B14: 예금이자수입 | C14: 소계
B15: 사업외수익 | C15: 잡수입 | G15: {=SUMPRODUCT((활동비지출일별내역!$B$7:$B$248=B15)*(활동비지출일별내역!#REF!=정산보고서!C15)*(활동비지출일별내역!$C$7:$C$248=정산보고서!D15)*활동비지출일별내역!#REF!)} -> #REF! | H15: {=SUMPRODUCT((활동비지출일별내역!$B$7:$B$248=B15)*(활동비지출일별내역!#REF!=정산보고서!C15)*(활동비지출일별내역!$C$7:$C$248=정산보고서!D15)*활동비지출일별내역!$G$7:$G$248)} -> #REF!
B16: 사업외비용 | C16: 잡지출 | G16: {=SUMPRODUCT((활동비지출일별내역!$B$7:$B$248=B16)*(활동비지출일별내역!#REF!=정산보고서!C16)*(활동비지출일별내역!$C$7:$C$248=정산보고서!D16)*활동비지출일별내역!#REF!)} -> #REF! | H16: {=SUMPRODUCT((활동비지출일별내역!$B$7:$B$248=B16)*(활동비지출일별내역!#REF!=정산보고서!C16)*(활동비지출일별내역!$C$7:$C$248=정산보고서!D16)*활동비지출일별내역!$G$7:$G$248)} -> #REF!
B17: 잡수입 | C17: 소계
B18: 인건비 | C18: 전담인력 | D18: 급여 | F18: 10000000 | G18: {=SUMPRODUCT((활동비지출일별내역!$B$7:$B$248=B18)*(활동비지출일별내역!#REF!=정산보고서!C18)*(활동비지출일별내역!$C$7:$C$248=정산보고서!D18)*활동비지출일별내역!#REF!)} -> #REF! | H18: {=SUMPRODUCT((활동비지출일별내역!$B$7:$B$248=B18)*(활동비지출일별내역!#REF!=정산보고서!C18)*(활동비지출일별내역!$C$7:$C$248=정산보고서!D18)*활동비지출일별내역!$G$7:$G$248)} -> #REF! | I18: =F18-H18 -> #REF! | J18: =H18/F18 -> #REF!
B19: 인건비 | C19: 인건비 | D19: 사회보험 | G19: {=SUMPRODUCT((활동비지출일별내역!$B$7:$B$248=B19)*(활동비지출일별내역!#REF!=정산보고서!C19)*(활동비지출일별내역!$C$7:$C$248=정산보고서!D19)*활동비지출일별내역!#REF!)} -> #REF! | H19: {=SUMPRODUCT((활동비지출일별내역!$B$7:$B$248=B19)*(활동비지출일별내역!#REF!=정산보고서!C19)*(활동비지출일별내역!$C$7:$C$248=정산보고서!D19)*활동비지출일별내역!$G$7:$G$248)} -> #REF! | I19: =F19-H19 -> #REF!
B20: 인건비 | C20: 소계 | F20: =SUM(F18:F19) -> 10000000
B21: 사업비 | C21: 학교참여수거모델개발 | D21: 개발회의비 | F21: 4250000 | G21: {=SUMPRODUCT((활동비지출일별내역!$B$7:$B$248=B21)*(활동비지출일별내역!#REF!=정산보고서!C21)*(활동비지출일별내역!$C$7:$C$248=정산보고서!D21)*활동비지출일별내역!#REF!)} -> #REF! | H21: {=SUMPRODUCT((활동비지출일별내역!$B$7:$B$248=B21)*(활동비지출일별내역!#REF!=정산보고서!C21)*(활동비지출일별내역!$C$7:$C$248=정산보고서!D21)*활동비지출일별내역!$G$7:$G$248)} -> #REF! | I21: =F21-H21 -> #REF! | J21: =H21/F21 -> #REF!
B22: 사업비 | C22: 학교참여수거모델개발 | D22: 학교수거공간조성비 | F22: 2400000 | G22: {=SUMPRODUCT((활동비지출일별내역!$B$7:$B$248=B22)*(활동비지출일별내역!#REF!=정산보고서!C22)*(활동비지출일별내역!$C$7:$C$248=정산보고서!D22)*활동비지출일별내역!#REF!)} -> #REF! | H22: {=SUMPRODUCT((활동비지출일별내역!$B$7:$B$248=B22)*(활동비지출일별내역!#REF!=정산보고서!C22)*(활동비지출일별내역!$C$7:$C$248=정산보고서!D22)*활동비지출일별내역!$G$7:$G$248)} -> #REF! | I22: =F22-H22 -> #REF! | J22: =H22/F22 -> #REF!
B23: 사업비 | C23: 학교참여수거모델개발 | D23: 자원순환교육 | F23: 5080000 | G23: {=SUMPRODUCT((활동비지출일별내역!$B$7:$B$248=B23)*(활동비지출일별내역!#REF!=정산보고서!C23)*(활동비지출일별내역!$C$7:$C$248=정산보고서!D23)*활동비지출일별내역!#REF!)} -> #REF! | H23: {=SUMPRODUCT((활동비지출일별내역!$B$7:$B$248=B23)*(활동비지출일별내역!#REF!=정산보고서!C23)*(활동비지출일별내역!$C$7:$C$248=정산보고서!D23)*활동비지출일별내역!$G$7:$G$248)} -> #REF! | I23: =F23-H23 -> #REF! | J23: =H23/F23 -> #REF!
B24: 사업비 | C24: 학교참여수거모델개발 | D24: 종이팩수거 | F24: 1120000 | G24: {=SUMPRODUCT((활동비지출일별내역!$B$7:$B$248=B24)*(활동비지출일별내역!#REF!=정산보고서!C24)*(활동비지출일별내역!$C$7:$C$248=정산보고서!D24)*활동비지출일별내역!#REF!)} -> #REF! | H24: {=SUMPRODUCT((활동비지출일별내역!$B$7:$B$248=B24)*(활동비지출일별내역!#REF!=정산보고서!C24)*(활동비지출일별내역!$C$7:$C$248=정산보고서!D24)*활동비지출일별내역!$G$7:$G$248)} -> #REF! | I24: =F24-H24 -> #REF! | J24: =H24/F24 -> #REF!
B25: 사업비 | C25: 교육자료제작 | D25: 회의비 | F25: 2600000 | G25: {=SUMPRODUCT((활동비지출일별내역!$B$7:$B$248=B25)*(활동비지출일별내역!#REF!=정산보고서!C25)*(활동비지출일별내역!$C$7:$C$248=정산보고서!D25)*활동비지출일별내역!#REF!)} -> #REF! | H25: {=SUMPRODUCT((활동비지출일별내역!$B$7:$B$248=B25)*(활동비지출일별내역!#REF!=정산보고서!C25)*(활동비지출일별내역!$C$7:$C$248=정산보고서!D25)*활동비지출일별내역!$G$7:$G$248)} -> #REF! | I25: =F25-H25 -> #REF! | J25: =H25/F25 -> #REF!
B26: 사업비 | C26: 교육자료제작 | D26: 자료제작비 | F26: 1600000 | G26: {=SUMPRODUCT((활동비지출일별내역!$B$7:$B$248=B26)*(활동비지출일별내역!#REF!=정산보고서!C26)*(활동비지출일별내역!$C$7:$C$248=정산보고서!D26)*활동비지출일별내역!#REF!)} -> #REF! | H26: {=SUMPRODUCT((활동비지출일별내역!$B$7:$B$248=B26)*(활동비지출일별내역!#REF!=정산보고서!C26)*(활동비지출일별내역!$C$7:$C$248=정산보고서!D26)*활동비지출일별내역!$G$7:$G$248)} -> #REF! | I26: =F26-H26 -> #REF! | J26: =H26/F26 -> #REF!
B27: 사업비 | C27: 소계 | F27: =SUM(F21:F26) -> 17050000
B28: 관리운영비 | C28: 운영비 | D28: 출장비 | F28: 350000 | G28: {=SUMPRODUCT((활동비지출일별내역!$B$7:$B$248=B28)*(활동비지출일별내역!#REF!=정산보고서!C28)*(활동비지출일별내역!$C$7:$C$248=정산보고서!D28)*활동비지출일별내역!#REF!)} -> #REF! | H28: {=SUMPRODUCT((활동비지출일별내역!$B$7:$B$248=B28)*(활동비지출일별내역!#REF!=정산보고서!C28)*(활동비지출일별내역!$C$7:$C$248=정산보고서!D28)*활동비지출일별내역!$G$7:$G$248)} -> #REF! | I28: =F28-H28 -> #REF! | J28: =H28/F28 -> #REF!
B29: 관리운영비 | C29: 운영비 | D29: 사무용품비 | F29: 500000 | G29: {=SUMPRODUCT((활동비지출일별내역!$B$7:$B$248=B29)*(활동비지출일별내역!#REF!=정산보고서!C29)*(활동비지출일별내역!$C$7:$C$248=정산보고서!D29)*활동비지출일별내역!#REF!)} -> #REF! | H29: {=SUMPRODUCT((활동비지출일별내역!$B$7:$B$248=B29)*(활동비지출일별내역!#REF!=정산보고서!C29)*(활동비지출일별내역!$C$7:$C$248=정산보고서!D29)*활동비지출일별내역!$G$7:$G$248)} -> #REF! | I29: =F29-H29 -> #REF! | J29: =H29/F29 -> #REF!
B30: 관리운영비 | C30: 운영비 | D30: 우편료·수수료 등 | F30: 100000 | G30: {=SUMPRODUCT((활동비지출일별내역!$B$7:$B$248=B30)*(활동비지출일별내역!#REF!=정산보고서!C30)*(활동비지출일별내역!$C$7:$C$248=정산보고서!D30)*활동비지출일별내역!#REF!)} -> #REF! | H30: {=SUMPRODUCT((활동비지출일별내역!$B$7:$B$248=B30)*(활동비지출일별내역!#REF!=정산보고서!C30)*(활동비지출일별내역!$C$7:$C$248=정산보고서!D30)*활동비지출일별내역!$G$7:$G$248)} -> #REF! | I30: =F30-H30 -> #REF! | J30: =H30/F30 -> #REF!
B31: 관리운영비 | C31: 소계 | F31: =SUM(F28:F30) -> 950000 | G31: {=SUMPRODUCT((활동비지출일별내역!$B$7:$B$248=B31)*(활동비지출일별내역!#REF!=정산보고서!C31)*(활동비지출일별내역!$C$7:$C$248=정산보고서!D31)*활동비지출일별내역!#REF!)} -> #REF! | H31: {=SUMPRODUCT((활동비지출일별내역!$B$7:$B$248=B31)*(활동비지출일별내역!#REF!=정산보고서!C31)*(활동비지출일별내역!$C$7:$C$248=정산보고서!D31)*활동비지출일별내역!$G$7:$G$248)} -> #REF!
B32: 사업비 | C32: 총계 | F32: =SUM(F31,F27,F20) -> 28000000 | G32: =SUM(G7:G31) -> #REF! | H32: =SUM(H7:H31) -> #REF!

Sheet 결과정산보고서 (2)
A1: 시민아이디어지원사업 풀씨 11기 활동 정산보고서
A4: 팀명 | E4: 대표자 | G4: 활동기간 | H4: 2024.04.01 - 2024.9.30
A5: 활동명
A6: 예산계획서 ※ 지원 당시 또는 승인된 예산변경계획서 | E6: 정산보고서 ※실제 집행된 내용
A7: 구분 | D7: 금 액(원) | E7: 집행날짜 (통장거래내역과 동일) | F7: 내용(산출근거) | G7: 단위당 가격(원) | H7: 단위수량 | I7: 단위 | J7: 총금액 | K7: 비고 | L7: 사용액(원) | M7: 잔액(원)
B8: 세목 | C8: 세세목
A9: 사업비 | B9: 행사 | C9: 정책간담회 | D9: 700000 | E9: 3월 10일 | F9: 행사 장소 대관 | G9: 100,000 | H9: 3 | I9: 시간 | J9: =G9*H9 -> 300000 | K9: 장소: 토스강남점 | L9: =SUM(J9:J11) -> 570000 | M9: =D9-L9 -> 130000
E10: 3월 12일 | F10: 행사다과비(음료) | G10: 4000 | H10: 30 | I10: 명 | J10: =G10*H10 -> 120000 | K10: 투썸플레이스
E11: 3월 13일 | F11: 외부강사초청 | G11: 150000 | H11: 1 | I11: 명 | J11: =G11*H11 -> 150000 | K11: 김00박사
C12: 시민워크숍 | D12: 300000 | E12: 5월 4일 | F12: 참가자 상품 (아메리카노 쿠폰) | G12: 3000 | H12: 20 | I12: 명 | J12: =G12*H12 -> 60000 | K12: 오피스콘 이용 | L12: =J12 -> 60000 | M12: =D12-L12 -> 240000
B13: 교육책자 발간 | D13: 900000 | E13: 4월 10일 | F13: 외부전문가 감수비 | G13: 100,000 | H13: 1 | I13: 회 | J13: =G13*H13 -> 100000 | K13: 한국00연구소 이00박사 | L13: =SUM(J13:J17) -> 798500 | M13: =D13-L13 -> 101500
E14: 4월 12일 | F14: 책자 1종 디자인 및 인쇄비 (30권) | G14: 450000 | H14: 1 | I14: 회 | J14: =G14*H14 -> 450000 | K14: 풀씨디자인
E15: 4월 12일 | F15: 책자 발간 회의 식사 1차 | G15: 18500 | H15: 1 | I15: 회 | J15: =G15*H15 -> 18500 | K15: 3명, 풀씨마라탕
E16: 4월 12일 | F16: 배포 우편비 | G16: 2000 | H16: 100 | I16: 명 | J16: =G16*H16 -> 200000
E17: 4월 18일 | F17: 책자 발간 회의 식사 2차 | G17: 10000 | H17: 3 | I17: 명 | J17: =G17*H17 -> 30000 | K17: 풀씨반점
B18: 홍보비 | D18: 80000 | E18: 7월 2일 | F18: 행사 및 교육책자 광고(인스타) | G18: 80000 | H18: 1 | I18: 회 | J18: =G18*H18 -> 80000 | K18: 6월 1일~6월 8일(7일) | L18: =J18 -> 80000 | M18: =D18-L18 -> 0
A19: 소 계 | D19: =SUM(D7:D18) -> 1980000 | E19: 소 계 | L19: =SUM(L9:L18) -> 1508500 | M19: =D19-L19 -> 471500
A20: 운영비 | D20: 200000 | E20: 3월 13일 | F20: 금융수수료 | G20: 500 | H20: 1 | I20: 회 | J20: =G20*H20 -> 500 | K20: 이체 수수료 | L20: =SUM(J20:J25) -> 200000 | M20: =D20-L20 -> 0
E21: 3월 20일 | F21: 중간보고 회의 식비 | G21: 40000 | H21: 1 | I21: 회 | J21: =G21*H21 -> 40000 | K21: 3명, 풀씨반점
E22: 4월 2일 | F22: 사무용품 | G22: 99000 | H22: 1 | I22: 세트 | J22: =G22*H22 -> 99000 | K22: 모닝글로리
E23: 4월 10일 | F23: 금융수수료 | G23: 500 | H23: 1 | I23: 회 | J23: =G23*H23 -> 500 | K23: 이체 수수료
E24: 7월 8일 | F24: 결과보고서 회의 식비 | G24: 35000 | H24: 1 | I24: 회 | J24: =G24*H24 -> 35000 | K24: 3명, 풀씨반점
E25: 7월 8일 | F25: 결과보고서 회의 다과 | G25: 25000 | H25: 1 | I25: 회 | J25: =G25*H25 -> 25000 | K25: 3명, 스타벅스
A26: 합 계 | D26: =SUM(D9:D24)-D19 -> 2180000 | E26: * 최종잔액 10,000원 이상시 재단에 환급 | L26: =SUM(L20,L19) -> 1708500 | M26: =D26-L26 -> 471500
A27: 이자, 캐시백 | D27: 2300 | L27: 최종잔액 (통장잔액, 환급전) | M27: =M26+D27 -> 473800
A28: *첨부서류 : 활동비 통장거래내역 1부 활동비 사용기준표에 의하여 위와 같이 활동비 사용내역을 보고합니다. 년 월 일 팀명 또는 개인 : (인) (재)숲과나눔 이사장 귀하
