Workbook
Name ER: '4.관항목정리목록 (2)'!#REF!
Name 관리운영비: '4.관항목정리목록 (2)'!#REF!
Name 교육자료제작: '4.관항목정리목록 (2)'!#REF!
Name 사업외비용: '4.관항목정리목록 (2)'!#REF!
Name 사업외수입: '4.관항목정리목록 (2)'!#REF!
Name 세목: '4.관항목정리목록 (2)'!#REF!
Name 우산수리교육워크숍: '4.관항목정리목록 (2)'!#REF!
Name 운영비: '4.관항목정리목록 (2)'!#REF!
Name 유형: '4.관항목정리목록 (2)'!#REF!
Name 인건비: '4.관항목정리목록 (2)'!#REF!
Name 전담인력: '4.관항목정리목록 (2)'!#REF!
Name 증빙종류: '4.관항목정리목록 (2)'!#REF!
Name 학교참여수거모델개발: '4.관항목정리목록 (2)'!#REF!
Name 홍보비: '4.관항목정리목록 (2)'!#REF!
Name 후원금수입: '4.관항목정리목록 (2)'!#REF!
Name 관리운영비: #REF!
Name 우산수리교육워크숍: '결과정산보고서'!$C$9:$C$10
Name 사업외비용: #REF!
Name 사업외수입: #REF!
Name 교육자료제작: #REF!
Name 증빙종류: #REF!
Name 사업외비용: #REF!
Name 홍보비: #REF!
Name 사업비: '결과정산보고서'!$C$9:$C$13
Name 유형: #REF!
Name 전담인력: #REF!
Name 교육자료제작: #REF!
Name 관: #REF!
Name 세목: #REF!
Name 수입: '4.관항목정리목록 (2)'!$E$7:$G$7
Name 목: '4.관항목정리목록 (2)'!$D$4:$D$8
Name 수입: '결과정산보고서'!$D$40:$D$42
Name 학교참여수거모델개발: #REF!
Name 운영비: '결과정산보고서'!$C$16
Name 운영비: #REF!
Name 근거자료: #REF!
Name 관리운영비: #REF!
Name 우산수리교육워크숍: '예산계획서 입력_예시'!$C$9:$C$10
Name 관: '4.관항목정리목록 (2)'!$B$5:$B$8
Name 사업비: '예산계획서 입력_예시'!$C$9:$C$13
Name 인건비: #REF!
Name 후원금수입: #REF!
Name 유형: #REF!
Name 전담인력: #REF!
Name 관: #REF!
Name 후원금수입: #REF!
Name 학교참여수거모델개발: #REF!
Name 홍보비: #REF!
Name 근거자료: #REF!
Name ER: #REF!
Name 증빙종류: #REF!
Name 수입: '예산계획서 입력_예시'!$D$39:$D$41
Name 인건비: #REF!
Name ER: #REF!
Name 세목: #REF!
Name 사업외수입: #REF!
Name MY_FUNCTION1: LAMBDA('활동비지출일별내역'!$G$7+IF('활동비지출일별내역'!$B$8="수입",'활동비지출일별내역'!$G$8,(-1*'활동비지출일별내역'!$G$8)))

Sheet 결과정산보고서
A1: 시민아이디어지원사업 풀씨 12기 활동 정산보고서
N3: 정산보고서 작성 가이드 (연노랑색 셀만 편집/입력하시면 됩니다)
A4: 팀명 | C4: 안심이 | E4: 대표자 | F4: 이근희 | G4: 활동기간 | H4: 2025.04.01 - 09.30 | N4: ◀ | O4: 1. 팀명, 대표자, 활동명을 작성해주세요.
A5: 활동명 | C5: 안심이 모두를 : 위한 재난 안전 데이터
A6: 예산계획서 ※ 지원 당시 또는 승인된 예산변경계획서 | F6: 정산보고서 ※실제 집행된 내용
A7: 구분 | D7: 내용 | E7: 금 액(원) | F7: 내용(산출근거) | L7: 사용액(원) | M7: 잔액(원)
A8: 항 | B8: 세목 | C8: 세세목
A9: 사업비 | B9: 행사 | C9: 시민워크숍 | D9: 식사 및 다과 15,000 x 3회 x 10인 = 450,000원 | E9: 450000 | F9: 6월 25일/밋앤핵 다과/(주)우아한형제들/175,900 6월 25일/밋앤핵 다과2/(주)우아한형제들/76,500 9월 11일/FTO 다과/(주)시티플러스 제2터미널점/79,036 9월 24일/인터뷰 다과/스타벅스코리아/27,600 | L9: =SUMIF('활동비지출일별내역'!C$7:C$168,'결과정산보고서'!C9,'활동비지출일별내역'!G$7:G$168) -> 359036 | M9: =E9-L9 -> 90964 | N9: ◀ | O9: 2. 지원서에 쓰셨던 예산계획서에 맞게 세목, 세세목, 내용, 금액을 작성해주세요. ★하단 맨 우측의 '예산계획서 입력_예시'를 참고해주세요. ★세목, 세세목이 더 적은 경우 행 삭제를 하셔도 되고, 그대로 두셔도 됩니다. ★세세목 이름이 동일하게 겹치지 않도록 해주세요. Ex) 세목1이 행사1, 세목2가 행사2라서 세세목1, 세세목2 모두 다과비라면, 세세목1에는 다과비1, 세세목2에는 다과비2 로 작성하셔서 뒤에 숫자로 구분해주세요. 3. 정산보고서 내용 부분은 하단 두번째 탭 '활동비지출일별내역'을 작성하시면 자동으로 입력됩니다. (하단 두번째 탭 부분을 꼭 작성해주세요)
C10: 전문가 간담회 | D10: 발제비 및 회의 수당 100,000 x 5회 = 500,000원 | E10: 500000 | F10: 9월 18일/이준기(장애인 활동지원사)/이준기/100,000 9월 22일/김용양(장애인 활동지원사)/김용양/100,000 | L10: =SUMIF('활동비지출일별내역'!C$7:C$168,'결과정산보고서'!C10,'활동비지출일별내역'!G$7:G$168) -> 200000 | M10: =E10-L10 -> 300000
B11: 데이터 수집 | C11: 인터뷰 | D11: 설문조사 5,000 x 240인 = 1,200,000원 개별 인터뷰 비용 12인 x 100,000 = 1,200,000원 *사유서 제출로 예산 세부 내역 변경함. | E11: 1200000 | F11: 9월 18일/장혜정(발달장애 청년허브 사부작)/장혜정/100,000 9월 20일/정지원(발달장애 청년허브 사부작)/정지원/100,000 9월 22일/여인찬(발달장애 청년허브 사부작/여인찬/100,000 9월 25일/김새봄(영유아 동반자)/김새봄/100,000 9월 25일/Clarissa Fionna(외국인 유학생)/Clarissa Fionna/100,000 9월 25일 /Coppoolse Anneke(외국인 노동자, 반려동물 동반자)/Coppoolse Anneke/100,000 9월 27일/김지연(영유아 동반자)/김지연/100,000 9월 29일/Sor Sythem(외국인 노동자)/Sor Sythem/100,000 9월 29일/Hanokers(외국인 노동자)/한옥커스(Hanokers)/100,000 9월 29일/Dewan Jana(외국인 노동자)/Dewan Jana/100,000 | L11: =SUMIF('활동비지출일별내역'!C$7:C$168,'결과정산보고서'!C11,'활동비지출일별내역'!G$7:G$168) -> 1000000 | M11: =E11-L11 -> 200000
B12: 홍보비 | C12: 웹사이트 | D12: 웹사이트 디자인 500,000 x 1식 = 500,000원 | E12: 500000 | F12: 웹사이트 디자인 툴 FIGMA 사용 7월 16일/웹사이트디자인 FIGMA-jul/FIGMA/62,945 8월16일/웹사이트디자인 FIGMA-aug/FIGMA/63,042 9월 16일/웹사이트디자인 FIGMA-sep/FIGMA /31,658 웹사이트 디자인 및 개발 9월 24일/김성준-웹사이트 디자인/김성준/310,080 | L12: =SUMIF('활동비지출일별내역'!C$7:C$168,'결과정산보고서'!C12,'활동비지출일별내역'!G$7:G$168) -> 467725 | M12: =E12-L12 -> 32275
C13: 홍보물 | D13: SNS 홍보물 및 발표 자료 디자인 310,000 x 1식 = 350,000원 | E13: 350000 | F13: 9월 4일/김정현-홍보물 디자인/김정현/319,200 | L13: =SUMIF('활동비지출일별내역'!C$7:C$168,'결과정산보고서'!C13,'활동비지출일별내역'!G$7:G$168) -> 319200 | M13: =E13-L13 -> 30800
B14: 세금 | C14: 세금 | D14: 원천징수액 | F14: 10월11일/재단법인 숲과나눔 김정현-홍보물 디자인 = 30,800 김성준-웹사이트 디자인 = 29,920 합계 = 60,720 | L14: 60720 | M14: 60720
C15: 수입 | D15: 소 계 | E15: =SUM(E7:E13) -> 3000000 | F15: 소 계 | L15: =SUM(L9:L14) -> 2406681 | M15: =E15-L15 -> 593319
A16: 운영비 | C16: 운영비 | M16: =E16-L16 -> 0
B17: 수입 | C17: 합 계 | E17: =SUM(E9:E16)-E15 -> 3000000 | F17: 잔액환급여부 | L17: =SUM(L16,L15) -> 2406681 | M17: =E17-L17 -> 593319 | N17: ◀ | O17: 4. 자동으로 계산된 합계, 이자, 캐시백, 환급액을 확인하시고, 최종 정산일에 환급필요가 떴을 경우 잔액 전부 환급해주시면 됩니다.
B18: 이자, 캐시백 | E18: =SUMIF('활동비지출일별내역'!C6:C168,"이자",'활동비지출일별내역'!G6:G168)+SUMIF('활동비지출일별내역'!C6:C168,"캐시백",'활동비지출일별내역'!G6:G168) -> 13960 | F18: 환급액 | G18: =IF(M18<=10000,0,M18) -> 607279 | H18: =IF(G18>0,"환급요망","환급불필요") -> 환급요망 | I18: 환급날짜 | J18: 10월11일 | L18: 최종잔액 (통장잔액, 환급전) | M18: =M17+E18 -> 607279
A19: * 첨부서류 : 활동비 통장거래내역 1부, 90만원 이상 항목의 견적서 활동비 사용기준표에 의하여 위와 같이 활동비 사용내역을 보고합니다. 2025 년 10월 11일 팀명 또는 개인 : 안심이 (인) (재)숲과나눔 이사장 귀하 | N19: ◀ | O19: 5. 최종 보고일, 서명을 완료하여 제출해주세요.
D40: 이자
D41: 캐시백
D42: 활동비

Sheet 활동비지출일별내역
A1: 시민아이디어지원사업 풀씨 11기 활동비지출일별내역 <2025.04.01 ∼ 2025.09.30>
A4: 팀명 | B4: 안심이 | C4: 거래은행 | D4: 토스뱅크 | E4: ↓지출한 사유를 자세히 적어주세요 | G4: 총 지출액 | H4: 최종 잔액 | I4: * 90만원 이상시 견적서 제출 *인건비 12만5천 이상시 세금 신고
A5: 계좌번호 | B5: 1001-8557-1370 | F5: 0 | G5: =SUMIF(B7:B169,"<>"&"수입",G7:G222) -> 2406681 | H5: =H169 -> 607279
A6: 순서 | B6: 항 | C6: 세세목 | D6: 거래일자 | E6: 내용 | F6: 거래처명 | G6: 수입/지출금액 | H6: 잔액 | I6: 구분 | J6: 비고
A7: 1 | B7: 수입 | C7: 활동비 | D7: 45379 | E7: 활동비입금 | F7: 재단법인 숲과나눔 | G7: 3000000 | H7: =F5+IF('활동비지출일별내역'!$B7="수입",'활동비지출일별내역'!$G7,(-1*'활동비지출일별내역'!$G7)) -> 3000000 | I7: 이체
A8: 2 | B8: 수입 | C8: 이자 | D8: 45380 | E8: 통장 이자 | F8: 토스뱅크 | G8: 127 | H8: =G7+IF('활동비지출일별내역'!$B8="수입",'활동비지출일별내역'!$G8,(-1*'활동비지출일별내역'!$G8)) -> 3000127 | I8: 이체
A9: 3 | B9: 수입 | C9: 이자 | D9: 45381 | E9: 통장 이자 | F9: 토스뱅크 | G9: 127 | H9: =H8+IF('활동비지출일별내역'!$B9="수입",'활동비지출일별내역'!$G9,(-1*'활동비지출일별내역'!$G9)) -> 3000254 | I9: 이체
A10: 4 | B10: 수입 | C10: 이자 | D10: 45382 | E10: 통장 이자 | F10: 토스뱅크 | G10: 127 | H10: =H9+IF('활동비지출일별내역'!$B10="수입",'활동비지출일별내역'!$G10,(-1*'활동비지출일별내역'!$G10)) -> 3000381 | I10: 이체
A11: 5 | B11: 수입 | C11: 이자 | D11: 45383 | E11: 통장 이자 | F11: 토스뱅크 | G11: 127 | H11: =H10+IF('활동비지출일별내역'!$B11="수입",'활동비지출일별내역'!$G11,(-1*'활동비지출일별내역'!$G11)) -> 3000508 | I11: 이체
A12: 6 | B12: 수입 | C12: 이자 | D12: 45384 | E12: 통장 이자 | F12: 토스뱅크 | G12: 127 | H12: =H11+IF('활동비지출일별내역'!$B12="수입",'활동비지출일별내역'!$G12,(-1*'활동비지출일별내역'!$G12)) -> 3000635 | I12: 이체
A13: 7 | B13: 수입 | C13: 이자 | D13: 45385 | E13: 통장 이자 | F13: 토스뱅크 | G13: 127 | H13: =H12+IF('활동비지출일별내역'!$B13="수입",'활동비지출일별내역'!$G13,(-1*'활동비지출일별내역'!$G13)) -> 3000762 | I13: 이체
A14: 8 | B14: 수입 | C14: 이자 | D14: 45386 | E14: 통장 이자 | F14: 토스뱅크 | G14: 127 | H14: =H13+IF('활동비지출일별내역'!$B14="수입",'활동비지출일별내역'!$G14,(-1*'활동비지출일별내역'!$G14)) -> 3000889 | I14: 이체
A15: 9 | B15: 수입 | C15: 이자 | D15: 45387 | E15: 통장 이자 | F15: 토스뱅크 | G15: 127 | H15: =H14+IF('활동비지출일별내역'!$B15="수입",'활동비지출일별내역'!$G15,(-1*'활동비지출일별내역'!$G15)) -> 3001016 | I15: 이체
A16: 10 | B16: 수입 | C16: 이자 | D16: 45388 | E16: 통장 이자 | F16: 토스뱅크 | G16: 127 | H16: =H15+IF('활동비지출일별내역'!$B16="수입",'활동비지출일별내역'!$G16,(-1*'활동비지출일별내역'!$G16)) -> 3001143 | I16: 이체
A17: 11 | B17: 수입 | C17: 이자 | D17: 45389 | E17: 통장 이자 | F17: 토스뱅크 | G17: 128 | H17: =H16+IF('활동비지출일별내역'!$B17="수입",'활동비지출일별내역'!$G17,(-1*'활동비지출일별내역'!$G17)) -> 3001271 | I17: 이체
A18: 12 | B18: 수입 | C18: 이자 | D18: 45390 | E18: 통장 이자 | F18: 토스뱅크 | G18: 128 | H18: =H17+IF('활동비지출일별내역'!$B18="수입",'활동비지출일별내역'!$G18,(-1*'활동비지출일별내역'!$G18)) -> 3001399 | I18: 이체
A19: 13 | B19: 수입 | C19: 이자 | D19: 45391 | E19: 통장 이자 | F19: 토스뱅크 | G19: 128 | H19: =H18+IF('활동비지출일별내역'!$B19="수입",'활동비지출일별내역'!$G19,(-1*'활동비지출일별내역'!$G19)) -> 3001527 | I19: 이체
A20: 14 | B20: 수입 | C20: 이자 | D20: 45392 | E20: 통장 이자 | F20: 토스뱅크 | G20: 128 | H20: =H19+IF('활동비지출일별내역'!$B20="수입",'활동비지출일별내역'!$G20,(-1*'활동비지출일별내역'!$G20)) -> 3001655 | I20: 이체
... A120: 114 | B120: 사업비 | C120: 웹사이트 | D120: 45489 | E120: 웹사이트디자인 FIGMA-jul | F120: FIGMA | G120: 62945 | H120: =H119+IF('활동비지출일별내역'!$B120="수입",'활동비지출일별내역'!$G120,(-1*'활동비지출일별내역'!$G120)) -> 2698173 | I120: 카드
A121: 115 | B121: 수입 | C121: 이자 | D121: 8월1일 | E121: 통장 이자 | F121: 토스뱅크 | G121: 108 | H121: =H120+IF('활동비지출일별내역'!$B121="수입",'활동비지출일별내역'!$G121,(-1*'활동비지출일별내역'!$G121)) -> 2698281 | I121: 이체
A122: 116 | B122: 사업비 | C122: 웹사이트 | D122: 8월16일 | E122: 웹사이트디자인 FIGMA-aug | F122: FIGMA | G122: 63042 | H122: =H121+IF('활동비지출일별내역'!$B122="수입",'활동비지출일별내역'!$G122,(-1*'활동비지출일별내역'!$G122)) -> 2635239 | I122: 카드
A123: 117 | B123: 수입 | C123: 이자 | D123: 9월1일 | E123: 통장 이자 | F123: 토스뱅크 | G123: 196 | H123: =H122+IF('활동비지출일별내역'!$B123="수입",'활동비지출일별내역'!$G123,(-1*'활동비지출일별내역'!$G123)) -> 2635435 | I123: 이체
A124: 118 | B124: 사업비 | C124: 홍보물 | D124: 45904 | E124: 김정현-홍보물 디자인 | F124: 김정현 | G124: 319200 | H124: =H123+IF('활동비지출일별내역'!$B124="수입",'활동비지출일별내역'!$G124,(-1*'활동비지출일별내역'!$G124)) -> 2316235 | I124: 이체
A125: 119 | B125: 사업비 | C125: 시민워크숍 | D125: 45911 | E125: FTO 다과 | F125: (주)시티플러스 제2터미널점 | G125: 79036 | H125: =H124+IF('활동비지출일별내역'!$B125="수입",'활동비지출일별내역'!$G125,(-1*'활동비지출일별내역'!$G125)) -> 2237199 | I125: 카드
A126: 120 | B126: 사업비 | C126: 웹사이트 | D126: 45916 | E126: 웹사이트디자인 FIGMA-sep | F126: FIGMA | G126: 31658 | H126: =H125+IF('활동비지출일별내역'!$B126="수입",'활동비지출일별내역'!$G126,(-1*'활동비지출일별내역'!$G126)) -> 2205541 | I126: 카드
A127: 121 | B127: 사업비 | C127: 인터뷰 | D127: 45918 | E127: 장혜정 (발달장애 청년허브 사부작) | F127: 장혜정 | G127: 100000 | H127: =H126+IF('활동비지출일별내역'!$B127="수입",'활동비지출일별내역'!$G127,(-1*'활동비지출일별내역'!$G127)) -> 2105541 | I127: 이체
A128: 122 | B128: 사업비 | C128: 전문가 간담회 | D128: 45918 | E128: 이준기 (장애인 활동지원사) | F128: 이준기 | G128: 100000 | H128: =H127+IF('활동비지출일별내역'!$B128="수입",'활동비지출일별내역'!$G128,(-1*'활동비지출일별내역'!$G128)) -> 2005541 | I128: 이체
A129: 123 | B129: 사업비 | C129: 인터뷰 | D129: 45920 | E129: 정지원 (발달장애 청년허브 사부작) | F129: 정지원 | G129: 100000 | H129: =H128+IF('활동비지출일별내역'!$B129="수입",'활동비지출일별내역'!$G129,(-1*'활동비지출일별내역'!$G129)) -> 1905541 | I129: 이체
A130: 124 | B130: 사업비 | C130: 인터뷰 | D130: 45922 | E130: 여인찬 (발달장애 청년허브 사부작) | F130: 여인찬 | G130: 100000 | H130: =H129+IF('활동비지출일별내역'!$B130="수입",'활동비지출일별내역'!$G130,(-1*'활동비지출일별내역'!$G130)) -> 1805541 | I130: 이체
A131: 125 | B131: 사업비 | C131: 전문가 간담회 | D131: 45922 | E131: 김용양 (장애인 활동지원사) | F131: 김용양 | G131: 100000 | H131: =H130+IF('활동비지출일별내역'!$B131="수입",'활동비지출일별내역'!$G131,(-1*'활동비지출일별내역'!$G131)) -> 1705541 | I131: 이체
A132: 126 | B132: 사업비 | C132: 웹사이트 | D132: 45924 | E132: 김성준-웹사이트 디자인 | F132: 김성준 | G132: 310080 | H132: =H131+IF('활동비지출일별내역'!$B132="수입",'활동비지출일별내역'!$G132,(-1*'활동비지출일별내역'!$G132)) -> 1395461 | I132: 이체
A133: 127 | B133: 사업비 | C133: 시민워크숍 | D133: 45924 | E133: 인터뷰 다과 | F133: 스타벅스코리아 | G133: 27600 | H133: =H132+IF('활동비지출일별내역'!$B133="수입",'활동비지출일별내역'!$G133,(-1*'활동비지출일별내역'!$G133)) -> 1367861 | I133: 카드
A134: 128 | B134: 사업비 | C134: 인터뷰 | D134: 45925 | E134: 김새봄 (영유아 보호자) | F134: 김새봄 | G134: 100000 | H134: =H133+IF('활동비지출일별내역'!$B134="수입",'활동비지출일별내역'!$G134,(-1*'활동비지출일별내역'!$G134)) -> 1267861 | I134: 이체
A135: 129 | B135: 사업비 | C135: 인터뷰 | D135: 45925 | E135: Clarissa Fionna (외국인 유학생) | F135: Clarissa Fionna | G135: 100000 | H135: =H134+IF('활동비지출일별내역'!$B135="수입",'활동비지출일별내역'!$G135,(-1*'활동비지출일별내역'!$G135)) -> 1167861 | I135: 이체
... A140: 134 | B140: 사업비 | C140: 인터뷰 | D140: 45929 | E140: Dewan Jana (외국인 노동자) | F140: Dewan Jana | G140: 100000 | H140: =H139+IF('활동비지출일별내역'!$B140="수입",'활동비지출일별내역'!$G140,(-1*'활동비지출일별내역'!$G140)) -> 667861 | I140: 이체
A141: 135 | B141: 수입 | C141: 이자 | D141: 10월1일 | E141: 통장 이자 | F141: 토스뱅크 | G141: 138 | H141: =H140+IF('활동비지출일별내역'!$B141="수입",'활동비지출일별내역'!$G141,(-1*'활동비지출일별내역'!$G141)) -> 667999 | I141: 이체
A142: 136 | B142: 사업비 | C142: 세금 | D142: 10월11일 | E142: 원천징수액 입금 | F142: 재단법인 숲과나눔 | G142: 60720 | H142: =H141+IF('활동비지출일별내역'!$B142="수입",'활동비지출일별내역'!$G142,(-1*'활동비지출일별내역'!$G142)) -> 607279 | I142: 이체 | J142: 세금
A143: 137 | H143: =H142+IF('활동비지출일별내역'!$B143="수입",'활동비지출일별내역'!$G143,(-1*'활동비지출일별내역'!$G143)) -> 607279
A144: 138 | H144: =H143+IF('활동비지출일별내역'!$B144="수입",'활동비지출일별내역'!$G144,(-1*'활동비지출일별내역'!$G144)) -> 607279
A145: 139 | H145: =H144+IF('활동비지출일별내역'!$B145="수입",'활동비지출일별내역'!$G145,(-1*'활동비지출일별내역'!$G145)) -> 607279
...

Sheet 예산계획서 입력_예시
A1: 시민아이디어지원사업 풀씨 12기 활동 정산보고서
A4: 팀명 | C4: 안심이 | E4: 대표자 | G4: 활동기간 | H4: 2025.04.01 - 09.30
A5: 활동명 | C5: 안심이 모두를 : 위한 재난 안전 데이터
A6: 예산계획서 ※ 지원 당시 또는 승인된 예산변경계획서 | F6: 정산보고서 ※실제 집행된 내용 | N6: 예산계획서 입력 예시드립니다. 참고 부탁드립니다. (세목과 세세목이 동일한 경우 세세목만 입력하셔도 됩니다.)
A7: 구분 | D7: 내용 | E7: 금 액(원) | F7: 내용(산출근거) | L7: 사용액(원) | M7: 잔액(원)
A8: 항 | B8: 세목 | C8: 세세목
A9: 사업비 | B9: 행사 | C9: 시민워크숍 | D9: 식사 및 다과 15,000 x 3회 x 10인 = 450,000원 | E9: 450000 | F9: {=TEXTJOIN(CHAR(10),TRUE,IF('활동비지출일별내역'!C$7:C$168='예산계획서 입력_예시'!C9,#REF!,""))} -> #REF! | L9: =SUMIF('활동비지출일별내역'!C$7:C$168,'예산계획서 입력_예시'!C9,'활동비지출일별내역'!G$7:G$168) -> #N/A | M9: =E9-L9 -> #N/A
B10: 행사 | C10: 전문가 간담회 | D10: 발제비 및 회의 수당 100,000 x 5회 = 500,000원 | E10: 500000
B11: 데이터 수집 | C11: 인터뷰 | D11: 설문조사 5,000 x 240인 = 1,200,000원 개별 인터뷰 비용 12인 x 100,000 = 1,200,000원 *사유서 제출로 예산 세부 내역 변경함. | E11: 1200000 | F11: {=TEXTJOIN(CHAR(10),TRUE,IF('활동비지출일별내역'!C$7:C$168='예산계획서 입력_예시'!C10,#REF!,""))} -> #REF! | L11: =SUMIF('활동비지출일별내역'!C$7:C$168,'예산계획서 입력_예시'!C10,'활동비지출일별내역'!G$7:G$168) -> #N/A | M11: =E10-L11 -> #N/A
B12: 홍보비 | C12: 웹사이트 | D12: 웹사이트 디자인 500,000 x 1식 = 500,000원 | E12: 500000 | F12: {=TEXTJOIN(CHAR(10),TRUE,IF('활동비지출일별내역'!C$7:C$168='예산계획서 입력_예시'!C11,#REF!,""))} -> #REF! | L12: =SUMIF('활동비지출일별내역'!C$7:C$168,'예산계획서 입력_예시'!C11,'활동비지출일별내역'!G$7:G$168) -> #N/A | M12: =E11-L12 -> #N/A
B13: 홍보비 | C13: 홍보물 | D13: SNS 홍보물 및 발표 자료 디자인 310,000 x 1식 = 350,000원 | E13: 350000 | F13: {=TEXTJOIN(CHAR(10),TRUE,IF('활동비지출일별내역'!C$7:C$168='예산계획서 입력_예시'!C13,#REF!,""))} -> #REF! | L13: =SUMIF('활동비지출일별내역'!C$7:C$168,'예산계획서 입력_예시'!C13,'활동비지출일별내역'!G$7:G$168) -> #N/A | M13: =E13-L13 -> #N/A
B14: 이자 | C14: 이자
B15: 세금 | C15: 세금
C16: 수입 | D16: 소 계 | E16: =SUM(E7:E13) -> 3000000 | F16: 소 계 | L16: =SUM(L9:L13) -> #N/A | M16: =E16-L16 -> #N/A
B17: 수입 | C17: 합 계 | E17: =SUM(E9:E16)-E16 -> 3000000 | F17: 잔액환급여부 | L17: =SUM(#REF!,L16) -> #REF! | M17: =E17-L17 -> #REF!
A18: * 첨부서류 : 활동비 통장거래내역 1부, 90만원 이상 항목의 견적서 활동비 사용기준표에 의하여 위와 같이 활동비 사용내역을 보고합니다. 2025 년 10월 12일 팀명 또는 개인 : 안심이 (인) (재)숲과나눔 이사장 귀하
D39: 이자
D40: 캐시백
D41: 활동비

Sheet 4.관항목정리목록 (2)
B2: 최종 예산에 따라 관/세목/세세목을 정리해주세요. | V2: 관 | X2: 항
D3: 세세목
B4: 관 | C4: 세목 | D4: 열1 | E4: 열2 | F4: 열3 | G4: 열4 | V4: 복지부2005 | X4: 복지부2005 | Y4: 복지부2006 | Z4: 복지부2007 | AA4: 복지부2008 | AB4: 복지부2009 | AC4: 서울희망드림뱅크2009 | AD4: 국민은행2008 | AE4: 국민은행2008 | AF4: 씨티2009 | AG4: 경상회계 | AM4: 복지부2007 | AP4: 복지부2008 | AT4: 복지부2009 | AU4: 서울희망드림뱅크2009 | AV4: 국민은행2008 | AY4: 국민은행2008 | AZ4: 씨티2009 | BE4: 경상회계
B5: 사업비 | C5: 우산수리교육워크숍 | V5: 복지부2007 | Y5: 인건비 | Z5: 인건비 | AA5: 인건비 | AD5: 간접사업비 | AF5: 지역지도자양성 | AI5: 매롱 | AJ5: 얼레리 | AK5: 닐리리 | AZ5: 전문가전략회의 | BA5: 사례관리활동 | BB5: 경영컨설팅(전문가) | BC5: 운영비 | BD5: 총괄자 인건비
B6: 운영비 | C6: 홍보비 | V6: 복지부2008 | Y6: 사업경비 | Z6: 사업경비 | AA6: 사전관리 | AD6: 인건비 | AF6: 지역네트워크강화 | AI6: 매롱2 | AJ6: 얼레리2 | AK6: 닐리리2 | AZ6: 모형개발활동 | BA6: 지역지도자대표활동 | BB6: 경영컨설팅(산학협력) | BC6: 시스템분석 | BD6: 수행자인건비
B7: 수입 | C7: 수입 | E7: 이자 | F7: 캐시백 | G7: 활동비 | V7: 복지부2009 | AA7: 사후관리 | AF7: 업무시스템 | AI7: 매롱3 | AJ7: 얼레리3 | AK7: 닐리리3 | AZ7: 1차워크숍(전체) | BA7: 슈퍼비전회의 | BB7: 공동체 교육 | BC7: 시스템도입
C8: 운영비 | V8: 서울희망드림뱅크2009 | AF8: 운영비 | AI8: 매롱4 | AJ8: 얼레리4 | AK8: 닐리리4 | AZ8: 발표비 | BB8: 지회별 워크숍 | BC8: 회계감사비
V9: 국민은행2008 | AI9: 매롱5 | AJ9: 얼레리5 | AK9: 닐리리5 | AZ9: 발표자료 작성비 | BB9: 발표비

Sheet 정산보고서
C1: 통장입출금거래내역 | G1: =SUM(활동비지출일별내역!#REF!) -> #ERROR! | H1: =SUM('활동비지출일별내역'!G7:G248) -> #REF!
C2: 통장거래내역별수지현황 | G2: =SUM(G7:G31) -> #ERROR! | H2: =SUM(H7:H31) -> #ERROR!
C3: 차액 | G3: =G1-G2 -> #ERROR! | H3: =H1-H2 -> #REF!
B4: 2023년 초록열매성과확산프로젝트 사업비 수지현황
B6: 계정과목 | C6: 항 | D6: 목 | E6: 산출근거 | F6: 예산액 | G6: 수입총계 | H6: 지출총계 | I6: 집행잔액 | J6: 집행비율 | K6: 비고
B7: 예금대체 | C7: 예금간거래입금 | G7: =ARRAY_CONSTRAIN(ARRAYFORMULA(SUMPRODUCT((활동비지출일별내역!$B$7:$B$248=B7)*(활동비지출일별내역!#REF!=정산보고서!C7)*(활동비지출일별내역!$C$7:$C$248=정산보고서!D7)*활동비지출일별내역!#REF!)), 1, 1) -> #ERROR! | H7: =ARRAY_CONSTRAIN(ARRAYFORMULA(SUMPRODUCT((활동비지출일별내역!$B$7:$B$248=B7)*(활동비지출일별내역!#REF!=정산보고서!C7)*(활동비지출일별내역!$C$7:$C$248=정산보고서!D7)*활동비지출일별내역!$G$7:$G$248)), 1, 1) -> #ERROR!
B8: 예금대체 | C8: 예금간거래출금 | G8: =ARRAY_CONSTRAIN(ARRAYFORMULA(SUMPRODUCT((활동비지출일별내역!$B$7:$B$248=B8)*(활동비지출일별내역!#REF!=정산보고서!C8)*(활동비지출일별내역!$C$7:$C$248=정산보고서!D8)*활동비지출일별내역!#REF!)), 1, 1) -> #ERROR! | H8: =ARRAY_CONSTRAIN(ARRAYFORMULA(SUMPRODUCT((활동비지출일별내역!$B$7:$B$248=B8)*(활동비지출일별내역!#REF!=정산보고서!C8)*(활동비지출일별내역!$C$7:$C$248=정산보고서!D8)*활동비지출일별내역!$G$7:$G$248)), 1, 1) -> #ERROR!
B9: 예금대체 | C9: 소계
B10: 수입 | C10: 후원금수입 | D10: 지정후원금수입 | G10: =ARRAY_CONSTRAIN(ARRAYFORMULA(SUMPRODUCT((활동비지출일별내역!$B$7:$B$248=B10)*(활동비지출일별내역!#REF!=정산보고서!C10)*(활동비지출일별내역!$C$7:$C$248=정산보고서!D10)*활동비지출일별내역!#REF!)), 1, 1) -> #ERROR! | H10: =ARRAY_CONSTRAIN(ARRAYFORMULA(SUMPRODUCT((활동비지출일별내역!$B$7:$B$248=B10)*(활동비지출일별내역!#REF!=정산보고서!C10)*(활동비지출일별내역!$C$7:$C$248=정산보고서!D10)*활동비지출일별내역!$G$7:$G$248)), 1, 1) -> #ERROR!
B11: 사업수입 | C11: 소계
B12: 사업외수익 | C12: 예금이자수입 | G12: =ARRAY_CONSTRAIN(ARRAYFORMULA(SUMPRODUCT((활동비지출일별내역!$B$7:$B$248=B12)*(활동비지출일별내역!#REF!=정산보고서!C12)*(활동비지출일별내역!$C$7:$C$248=정산보고서!D12)*활동비지출일별내역!#REF!)), 1, 1) -> #ERROR! | H12: =ARRAY_CONSTRAIN(ARRAYFORMULA(SUMPRODUCT((활동비지출일별내역!$B$7:$B$248=B12)*(활동비지출일별내역!#REF!=정산보고서!C12)*(활동비지출일별내역!$C$7:$C$248=정산보고서!D12)*활동비지출일별내역!$G$7:$G$248)), 1, 1) -> #ERROR!
B13: 사업외비용 | C13: 선급법인세 | G13: =ARRAY_CONSTRAIN(ARRAYFORMULA(SUMPRODUCT((활동비지출일별내역!$B$7:$B$248=B13)*(활동비지출일별내역!#REF!=정산보고서!C13)*(활동비지출일별내역!$C$7:$C$248=정산보고서!D13)*활동비지출일별내역!#REF!)), 1, 1) -> #ERROR! | H13: =ARRAY_CONSTRAIN(ARRAYFORMULA(SUMPRODUCT((활동비지출일별내역!$B$7:$B$248=B13)*(활동비지출일별내역!#REF!=정산보고서!C13)*(활동비지출일별내역!$C$7:$C$248=정산보고서!D13)*활동비지출일별내역!$G$7:$G$248)), 1, 1) -> #ERROR!
B14: 예금이자수입 | C14: 소계
B15: 사업외수익 | C15: 잡수입 | G15: =ARRAY_CONSTRAIN(ARRAYFORMULA(SUMPRODUCT((활동비지출일별내역!$B$7:$B$248=B15)*(활동비지출일별내역!#REF!=정산보고서!C15)*(활동비지출일별내역!$C$7:$C$248=정산보고서!D15)*활동비지출일별내역!#REF!)), 1, 1) -> #ERROR! | H15: =ARRAY_CONSTRAIN(ARRAYFORMULA(SUMPRODUCT((활동비지출일별내역!$B$7:$B$248=B15)*(활동비지출일별내역!#REF!=정산보고서!C15)*(활동비지출일별내역!$C$7:$C$248=정산보고서!D15)*활동비지출일별내역!$G$7:$G$248)), 1, 1) -> #ERROR!
B16: 사업외비용 | C16: 잡지출 | G16: =ARRAY_CONSTRAIN(ARRAYFORMULA(SUMPRODUCT((활동비지출일별내역!$B$7:$B$248=B16)*(활동비지출일별내역!#REF!=정산보고서!C16)*(활동비지출일별내역!$C$7:$C$248=정산보고서!D16)*활동비지출일별내역!#REF!)), 1, 1) -> #ERROR! | H16: =ARRAY_CONSTRAIN(ARRAYFORMULA(SUMPRODUCT((활동비지출일별내역!$B$7:$B$248=B16)*(활동비지출일별내역!#REF!=정산보고서!C16)*(활동비지출일별내역!$C$7:$C$248=정산보고서!D16)*활동비지출일별내역!$G$7:$G$248)), 1, 1) -> #ERROR!
B17: 잡수입 | C17: 소계
B18: 인건비 | C18: 전담인력 | D18: 급여 | F18: 10000000 | G18: =ARRAY_CONSTRAIN(ARRAYFORMULA(SUMPRODUCT((활동비지출일별내역!$B$7:$B$248=B18)*(활동비지출일별내역!#REF!=정산보고서!C18)*(활동비지출일별내역!$C$7:$C$248=정산보고서!D18)*활동비지출일별내역!#REF!)), 1, 1) -> #ERROR! | H18: =ARRAY_CONSTRAIN(ARRAYFORMULA(SUMPRODUCT((활동비지출일별내역!$B$7:$B$248=B18)*(활동비지출일별내역!#REF!=정산보고서!C18)*(활동비지출일별내역!$C$7:$C$248=정산보고서!D18)*활동비지출일별내역!$G$7:$G$248)), 1, 1) -> #ERROR! | I18: =F18-H18 -> #ERROR! | J18: =H18/F18 -> #ERROR!
B19: 인건비 | C19: 인건비 | D19: 사회보험 | G19: =ARRAY_CONSTRAIN(ARRAYFORMULA(SUMPRODUCT((활동비지출일별내역!$B$7:$B$248=B19)*(활동비지출일별내역!#REF!=정산보고서!C19)*(활동비지출일별내역!$C$7:$C$248=정산보고서!D19)*활동비지출일별내역!#REF!)), 1, 1) -> #ERROR! | H19: =ARRAY_CONSTRAIN(ARRAYFORMULA(SUMPRODUCT((활동비지출일별내역!$B$7:$B$248=B19)*(활동비지출일별내역!#REF!=정산보고서!C19)*(활동비지출일별내역!$C$7:$C$248=정산보고서!D19)*활동비지출일별내역!$G$7:$G$248)), 1, 1) -> #ERROR! | I19: =F19-H19 -> #ERROR!
B20: 인건비 | C20: 소계 | F20: =SUM(F18:F19) -> 10000000
B21: 사업비 | C21: 학교참여수거모델개발 | D21: 개발회의비 | F21: 4250000 | G21: =ARRAY_CONSTRAIN(ARRAYFORMULA(SUMPRODUCT((활동비지출일별내역!$B$7:$B$248=B21)*(활동비지출일별내역!#REF!=정산보고서!C21)*(활동비지출일별내역!$C$7:$C$248=정산보고서!D21)*활동비지출일별내역!#REF!)), 1, 1) -> #ERROR! | H21: =ARRAY_CONSTRAIN(ARRAYFORMULA(SUMPRODUCT((활동비지출일별내역!$B$7:$B$248=B21)*(활동비지출일별내역!#REF!=정산보고서!C21)*(활동비지출일별내역!$C$7:$C$248=정산보고서!D21)*활동비지출일별내역!$G$7:$G$248)), 1, 1) -> #ERROR! | I21: =F21-H21 -> #ERROR! | J21: =H21/F21 -> #ERROR!
B22: 사업비 | C22: 학교참여수거모델개발 | D22: 학교수거공간조성비 | F22: 2400000 | G22: =ARRAY_CONSTRAIN(ARRAYFORMULA(SUMPRODUCT((활동비지출일별내역!$B$7:$B$248=B22)*(활동비지출일별내역!#REF!=정산보고서!C22)*(활동비지출일별내역!$C$7:$C$248=정산보고서!D22)*활동비지출일별내역!#REF!)), 1, 1) -> #ERROR! | H22: =ARRAY_CONSTRAIN(ARRAYFORMULA(SUMPRODUCT((활동비지출일별내역!$B$7:$B$248=B22)*(활동비지출일별내역!#REF!=정산보고서!C22)*(활동비지출일별내역!$C$7:$C$248=정산보고서!D22)*활동비지출일별내역!$G$7:$G$248)), 1, 1) -> #ERROR! | I22: =F22-H22 -> #ERROR! | J22: =H22/F22 -> #ERROR!
B23: 사업비 | C23: 학교참여수거모델개발 | D23: 자원순환교육 | F23: 5080000 | G23: =ARRAY_CONSTRAIN(ARRAYFORMULA(SUMPRODUCT((활동비지출일별내역!$B$7:$B$248=B23)*(활동비지출일별내역!#REF!=정산보고서!C23)*(활동비지출일별내역!$C$7:$C$248=정산보고서!D23)*활동비지출일별내역!#REF!)), 1, 1) -> #ERROR! | H23: =ARRAY_CONSTRAIN(ARRAYFORMULA(SUMPRODUCT((활동비지출일별내역!$B$7:$B$248=B23)*(활동비지출일별내역!#REF!=정산보고서!C23)*(활동비지출일별내역!$C$7:$C$248=정산보고서!D23)*활동비지출일별내역!$G$7:$G$248)), 1, 1) -> #ERROR! | I23: =F23-H23 -> #ERROR! | J23: =H23/F23 -> #ERROR!
B24: 사업비 | C24: 학교참여수거모델개발 | D24: 종이팩수거 | F24: 1120000 | G24: =ARRAY_CONSTRAIN(ARRAYFORMULA(SUMPRODUCT((활동비지출일별내역!$B$7:$B$248=B24)*(활동비지출일별내역!#REF!=정산보고서!C24)*(활동비지출일별내역!$C$7:$C$248=정산보고서!D24)*활동비지출일별내역!#REF!)), 1, 1) -> #ERROR! | H24: =ARRAY_CONSTRAIN(ARRAYFORMULA(SUMPRODUCT((활동비지출일별내역!$B$7:$B$248=B24)*(활동비지출일별내역!#REF!=정산보고서!C24)*(활동비지출일별내역!$C$7:$C$248=정산보고서!D24)*활동비지출일별내역!$G$7:$G$248)), 1, 1) -> #ERROR! | I24: =F24-H24 -> #ERROR! | J24: =H24/F24 -> #ERROR!
B25: 사업비 | C25: 교육자료제작 | D25: 회의비 | F25: 2600000 | G25: =ARRAY_CONSTRAIN(ARRAYFORMULA(SUMPRODUCT((활동비지출일별내역!$B$7:$B$248=B25)*(활동비지출일별내역!#REF!=정산보고서!C25)*(활동비지출일별내역!$C$7:$C$248=정산보고서!D25)*활동비지출일별내역!#REF!)), 1, 1) -> #ERROR! | H25: =ARRAY_CONSTRAIN(ARRAYFORMULA(SUMPRODUCT((활동비지출일별내역!$B$7:$B$248=B25)*(활동비지출일별내역!#REF!=정산보고서!C25)*(활동비지출일별내역!$C$7:$C$248=정산보고서!D25)*활동비지출일별내역!$G$7:$G$248)), 1, 1) -> #ERROR! | I25: =F25-H25 -> #ERROR! | J25: =H25/F25 -> #ERROR!
B26: 사업비 | C26: 교육자료제작 | D26: 자료제작비 | F26: 1600000 | G26: =ARRAY_CONSTRAIN(ARRAYFORMULA(SUMPRODUCT((활동비지출일별내역!$B$7:$B$248=B26)*(활동비지출일별내역!#REF!=정산보고서!C26)*(활동비지출일별내역!$C$7:$C$248=정산보고서!D26)*활동비지출일별내역!#REF!)), 1, 1) -> #ERROR! | H26: =ARRAY_CONSTRAIN(ARRAYFORMULA(SUMPRODUCT((활동비지출일별내역!$B$7:$B$248=B26)*(활동비지출일별내역!#REF!=정산보고서!C26)*(활동비지출일별내역!$C$7:$C$248=정산보고서!D26)*활동비지출일별내역!$G$7:$G$248)), 1, 1) -> #ERROR! | I26: =F26-H26 -> #ERROR! | J26: =H26/F26 -> #ERROR!
B27: 사업비 | C27: 소계 | F27: =SUM(F21:F26) -> 17050000
B28: 관리운영비 | C28: 운영비 | D28: 출장비 | F28: 350000 | G28: =ARRAY_CONSTRAIN(ARRAYFORMULA(SUMPRODUCT((활동비지출일별내역!$B$7:$B$248=B28)*(활동비지출일별내역!#REF!=정산보고서!C28)*(활동비지출일별내역!$C$7:$C$248=정산보고서!D28)*활동비지출일별내역!#REF!)), 1, 1) -> #ERROR! | H28: =ARRAY_CONSTRAIN(ARRAYFORMULA(SUMPRODUCT((활동비지출일별내역!$B$7:$B$248=B28)*(활동비지출일별내역!#REF!=정산보고서!C28)*(활동비지출일별내역!$C$7:$C$248=정산보고서!D28)*활동비지출일별내역!$G$7:$G$248)), 1, 1) -> #ERROR! | I28: =F28-H28 -> #ERROR! | J28: =H28/F28 -> #ERROR!
B29: 관리운영비 | C29: 운영비 | D29: 사무용품비 | F29: 500000 | G29: =ARRAY_CONSTRAIN(ARRAYFORMULA(SUMPRODUCT((활동비지출일별내역!$B$7:$B$248=B29)*(활동비지출일별내역!#REF!=정산보고서!C29)*(활동비지출일별내역!$C$7:$C$248=정산보고서!D29)*활동비지출일별내역!#REF!)), 1, 1) -> #ERROR! | H29: =ARRAY_CONSTRAIN(ARRAYFORMULA(SUMPRODUCT((활동비지출일별내역!$B$7:$B$248=B29)*(활동비지출일별내역!#REF!=정산보고서!C29)*(활동비지출일별내역!$C$7:$C$248=정산보고서!D29)*활동비지출일별내역!$G$7:$G$248)), 1, 1) -> #ERROR! | I29: =F29-H29 -> #ERROR! | J29: =H29/F29 -> #ERROR!
B30: 관리운영비 | C30: 운영비 | D30: 우편료·수수료 등 | F30: 100000 | G30: =ARRAY_CONSTRAIN(ARRAYFORMULA(SUMPRODUCT((활동비지출일별내역!$B$7:$B$248=B30)*(활동비지출일별내역!#REF!=정산보고서!C30)*(활동비지출일별내역!$C$7:$C$248=정산보고서!D30)*활동비지출일별내역!#REF!)), 1, 1) -> #ERROR! | H30: =ARRAY_CONSTRAIN(ARRAYFORMULA(SUMPRODUCT((활동비지출일별내역!$B$7:$B$248=B30)*(활동비지출일별내역!#REF!=정산보고서!C30)*(활동비지출일별내역!$C$7:$C$248=정산보고서!D30)*활동비지출일별내역!$G$7:$G$248)), 1, 1) -> #ERROR! | I30: =F30-H30 -> #ERROR! | J30: =H30/F30 -> #ERROR!
B31: 관리운영비 | C31: 소계 | F31: =SUM(F28:F30) -> 950000 | G31: =ARRAY_CONSTRAIN(ARRAYFORMULA(SUMPRODUCT((활동비지출일별내역!$B$7:$B$248=B31)*(활동비지출일별내역!#REF!=정산보고서!C31)*(활동비지출일별내역!$C$7:$C$248=정산보고서!D31)*활동비지출일별내역!#REF!)), 1, 1) -> #ERROR! | H31: =ARRAY_CONSTRAIN(ARRAYFORMULA(SUMPRODUCT((활동비지출일별내역!$B$7:$B$248=B31)*(활동비지출일별내역!#REF!=정산보고서!C31)*(활동비지출일별내역!$C$7:$C$248=정산보고서!D31)*활동비지출일별내역!$G$7:$G$248)), 1, 1) -> #ERROR!
B32: 사업비 | C32: 총계 | F32: =SUM(F31,F27,F20) -> 28000000 | G32: =SUM(G7:G31) -> #ERROR! | H32: =SUM(H7:H31) -> #ERROR!

Sheet 결과정산보고서 (2)
A1: 시민아이디어지원사업 풀씨 11기 활동 정산보고서
A4: 팀명 | E4: 대표자 | G4: 활동기간 | H4: 2024.04.01 - 2024.9.30
A5: 활동명
A6: 예산계획서 ※ 지원 당시 또는 승인된 예산변경계획서 | E6: 정산보고서 ※실제 집행된 내용
A7: 구분 | D7: 금 액(원) | E7: 집행날짜 (통장거래내역과 동일) | F7: 내용(산출근거) | G7: 단위당 가격(원) | H7: 단위수량 | I7: 단위 | J7: 총금액 | K7: 비고 | L7: 사용액(원) | M7: 잔액(원)
B8: 세목 | C8: 세세목
A9: 사업비 | B9: 행사 | C9: 정책간담회 | D9: 700000 | E9: 3월 10일 | F9: 행사 장소 대관 | G9: 100,000 | H9: 3 | I9: 시간 | J9: =G9*H9 -> 300000 | K9: 장소: 토스강남점 | L9: =SUM(J9:J11) -> 570000 | M9: =D9-L9 -> 130000
E10: 3월 12일 | F10: 행사다과비(음료) | G10: 4000 | H10: 30 | I10: 명 | J10: =G10*H10 -> 120000 | K10: 투썸플레이스
E11: 3월 13일 | F11: 외부강사초청 | G11: 150000 | H11: 1 | I11: 명 | J11: =G11*H11 -> 150000 | K11: 김00박사
C12: 시민워크숍 | D12: 300000 | E12: 5월 4일 | F12: 참가자 상품 (아메리카노 쿠폰) | G12: 3000 | H12: 20 | I12: 명 | J12: =G12*H12 -> 60000 | K12: 오피스콘 이용 | L12: =J12 -> 60000 | M12: =D12-L12 -> 240000
B13: 교육책자 발간 | D13: 900000 | E13: 4월 10일 | F13: 외부전문가 감수비 | G13: 100,000 | H13: 1 | I13: 회 | J13: =G13*H13 -> 100000 | K13: 한국00연구소 이00박사 | L13: =SUM(J13:J17) -> 798500 | M13: =D13-L13 -> 101500
E14: 4월 12일 | F14: 책자 1종 디자인 및 인쇄비 (30권) | G14: 450000 | H14: 1 | I14: 회 | J14: =G14*H14 -> 450000 | K14: 풀씨디자인
E15: 4월 12일 | F15: 책자 발간 회의 식사 1차 | G15: 18500 | H15: 1 | I15: 회 | J15: =G15*H15 -> 18500 | K15: 3명, 풀씨마라탕
E16: 4월 12일 | F16: 배포 우편비 | G16: 2000 | H16: 100 | I16: 명 | J16: =G16*H16 -> 200000
E17: 4월 18일 | F17: 책자 발간 회의 식사 2차 | G17: 10000 | H17: 3 | I17: 명 | J17: =G17*H17 -> 30000 | K17: 풀씨반점
B18: 홍보비 | D18: 80000 | E18: 7월 2일 | F18: 행사 및 교육책자 광고(인스타) | G18: 80000 | H18: 1 | I18: 회 | J18: =G18*H18 -> 80000 | K18: 6월 1일~6월 8일(7일) | L18: =J18 -> 80000 | M18: =D18-L18 -> 0
A19: 소 계 | D19: =SUM(D7:D18) -> 1980000 | E19: 소 계 | L19: =SUM(L9:L18) -> 1508500 | M19: =D19-L19 -> 471500
A20: 운영비 | D20: 200000 | E20: 3월 13일 | F20: 금융수수료 | G20: 500 | H20: 1 | I20: 회 | J20: =G20*H20 -> 500 | K20: 이체 수수료 | L20: =SUM(J20:J25) -> 200000 | M20: =D20-L20 -> 0
E21: 3월 20일 | F21: 중간보고 회의 식비 | G21: 40000 | H21: 1 | I21: 회 | J21: =G21*H21 -> 40000 | K21: 3명, 풀씨반점
E22: 4월 2일 | F22: 사무용품 | G22: 99000 | H22: 1 | I22: 세트 | J22: =G22*H22 -> 99000 | K22: 모닝글로리
E23: 4월 10일 | F23: 금융수수료 | G23: 500 | H23: 1 | I23: 회 | J23: =G23*H23 -> 500 | K23: 이체 수수료
E24: 7월 8일 | F24: 결과보고서 회의 식비 | G24: 35000 | H24: 1 | I24: 회 | J24: =G24*H24 -> 35000 | K24: 3명, 풀씨반점
E25: 7월 8일 | F25: 결과보고서 회의 다과 | G25: 25000 | H25: 1 | I25: 회 | J25: =G25*H25 -> 25000 | K25: 3명, 스타벅스
A26: 합 계 | D26: =SUM(D9:D24)-D19 -> 2180000 | E26: * 최종잔액 10,000원 이상시 재단에 환급 | L26: =SUM(L20,L19) -> 1708500 | M26: =D26-L26 -> 471500
A27: 이자, 캐시백 | D27: 2300 | L27: 최종잔액 (통장잔액, 환급전) | M27: =M26+D27 -> 473800
A28: *첨부서류 : 활동비 통장거래내역 1부 활동비 사용기준표에 의하여 위와 같이 활동비 사용내역을 보고합니다. 년 월 일 팀명 또는 개인 : (인) (재)숲과나눔 이사장 귀하
